<?xml version="1.0" ?>
<!-- Generated using onshape-to-robot -->
<!-- Onshape https://cad.onshape.com/documents/d7b35ee4f5c6e2f6765ac99d/w/8247700ba28623cceb6a50e3/e/901fe7942dc68bf3cfe1e829 -->
<robot name="bdx-mini">
  <!-- Dummy root link without inertia -->
  <link name="base_link"/>
  <!-- Fixed joint connecting base_link to sw_bd0 -->
  <joint name="fixed_base" type="fixed">
    <parent link="base_link"/>
    <child link="trunk_assembly"/>
    <origin xyz="0 0 0" rpy="0 0 0"/>
  </joint>

  <!-- Link trunk_assembly -->
  <link name="trunk_assembly">
    <inertial>
      <origin xyz="-0.0411008 8.5997e-05 0.0382607" rpy="0 0 0"/>
      <mass value="1.02895"/>
      <inertia ixx="0.00269519" ixy="-3.55783e-06" ixz="0.000324316" iyy="0.0053292" iyz="-1.46243e-06" izz="0.00418636"/>
    </inertial>
    <!-- Part fake_antenna -->
    <visual>
      <origin xyz="0.00675936 0.00148713 0.00422528" rpy="2.06672e-15 -1.15513e-14 2.53967e-15"/>
      <geometry>
        <mesh filename="package://open_duck_mini_description/meshes/fake_antenna.stl"/>
      </geometry>
      <material name="fake_antenna_material">
        <color rgba="0.611765 0.619608 0.627451 1.0"/>
      </material>
    </visual>
    <collision>
      <origin xyz="0.00675936 0.00148713 0.00422528" rpy="2.06672e-15 -1.15513e-14 2.53967e-15"/>
      <geometry>
        <mesh filename="package://open_duck_mini_description/meshes/fake_antenna.stl"/>
      </geometry>
    </collision>
    <!-- Part front_panel_v4 -->
    <visual>
      <origin xyz="6.91563e-16 1.32142e-12 -4.10429e-08" rpy="2.02937e-15 -1.15513e-14 2.53967e-15"/>
      <geometry>
        <mesh filename="package://open_duck_mini_description/meshes/front_panel_v4.stl"/>
      </geometry>
      <material name="front_panel_v4_material">
        <color rgba="1 1 1 1.0"/>
      </material>
    </visual>
    <collision>
      <origin xyz="6.91563e-16 1.32142e-12 -4.10429e-08" rpy="2.02937e-15 -1.15513e-14 2.53967e-15"/>
      <geometry>
        <mesh filename="package://open_duck_mini_description/meshes/front_panel_v4.stl"/>
      </geometry>
    </collision>
    <!-- Part e_stop_adapter_plate -->
    <visual>
      <origin xyz="7.05441e-16 4.27923e-16 -4.10396e-08" rpy="2.06672e-15 -1.15513e-14 2.53967e-15"/>
      <geometry>
        <mesh filename="package://open_duck_mini_description/meshes/e_stop_adapter_plate.stl"/>
      </geometry>
      <material name="e_stop_adapter_plate_material">
        <color rgba="1 1 1 1.0"/>
      </material>
    </visual>
    <collision>
      <origin xyz="7.05441e-16 4.27923e-16 -4.10396e-08" rpy="2.06672e-15 -1.15513e-14 2.53967e-15"/>
      <geometry>
        <mesh filename="package://open_duck_mini_description/meshes/e_stop_adapter_plate.stl"/>
      </geometry>
    </collision>
    <!-- Part front_cover -->
    <visual>
      <origin xyz="0.000284514 1.32144e-12 -4.10429e-08" rpy="2.36244e-15 -1.15513e-14 2.62734e-15"/>
      <geometry>
        <mesh filename="package://open_duck_mini_description/meshes/front_cover.stl"/>
      </geometry>
      <material name="front_cover_material">
        <color rgba="0.627451 0.627451 0.643137 1.0"/>
      </material>
    </visual>
    <collision>
      <origin xyz="0.000284514 1.32144e-12 -4.10429e-08" rpy="2.36244e-15 -1.15513e-14 2.62734e-15"/>
      <geometry>
        <mesh filename="package://open_duck_mini_description/meshes/front_cover.stl"/>
      </geometry>
    </collision>
    <!-- Part front_greeble -->
    <visual>
      <origin xyz="0.000284514 1.32144e-12 -4.10429e-08" rpy="2.36244e-15 -1.15513e-14 2.62734e-15"/>
      <geometry>
        <mesh filename="package://open_duck_mini_description/meshes/front_greeble.stl"/>
      </geometry>
      <material name="front_greeble_material">
        <color rgba="0.627451 0.627451 0.627451 1.0"/>
      </material>
    </visual>
    <collision>
      <origin xyz="0.000284514 1.32144e-12 -4.10429e-08" rpy="2.36244e-15 -1.15513e-14 2.62734e-15"/>
      <geometry>
        <mesh filename="package://open_duck_mini_description/meshes/front_greeble.stl"/>
      </geometry>
    </collision>
    <!-- Part e_stop_panel -->
    <visual>
      <origin xyz="7.05441e-16 4.27923e-16 -4.10396e-08" rpy="2.06672e-15 -1.15513e-14 2.53967e-15"/>
      <geometry>
        <mesh filename="package://open_duck_mini_description/meshes/e_stop_panel.stl"/>
      </geometry>
      <material name="e_stop_panel_material">
        <color rgba="1 1 1 1.0"/>
      </material>
    </visual>
    <collision>
      <origin xyz="7.05441e-16 4.27923e-16 -4.10396e-08" rpy="2.06672e-15 -1.15513e-14 2.53967e-15"/>
      <geometry>
        <mesh filename="package://open_duck_mini_description/meshes/e_stop_panel.stl"/>
      </geometry>
    </collision>
    <!-- Part power_switch -->
    <visual>
      <origin xyz="-0.157308 2.5484e-08 0.0595894" rpy="2.53967e-15 -1.5708 0"/>
      <geometry>
        <mesh filename="package://open_duck_mini_description/meshes/power_switch.stl"/>
      </geometry>
      <material name="power_switch_material">
        <color rgba="0.901961 0.901961 0.901961 1.0"/>
      </material>
    </visual>
    <collision>
      <origin xyz="-0.157308 2.5484e-08 0.0595894" rpy="2.53967e-15 -1.5708 0"/>
      <geometry>
        <mesh filename="package://open_duck_mini_description/meshes/power_switch.stl"/>
      </geometry>
    </collision>
    <!-- Part back_panel -->
    <visual>
      <origin xyz="6.89828e-16 4.29657e-16 -4.10396e-08" rpy="2.06672e-15 -1.15513e-14 2.53967e-15"/>
      <geometry>
        <mesh filename="package://open_duck_mini_description/meshes/back_panel.stl"/>
      </geometry>
      <material name="back_panel_material">
        <color rgba="1 1 1 1.0"/>
      </material>
    </visual>
    <collision>
      <origin xyz="6.89828e-16 4.29657e-16 -4.10396e-08" rpy="2.06672e-15 -1.15513e-14 2.53967e-15"/>
      <geometry>
        <mesh filename="package://open_duck_mini_description/meshes/back_panel.stl"/>
      </geometry>
    </collision>
    <!-- Part trunk_bottom -->
    <visual>
      <origin xyz="6.93285e-16 4.28849e-16 3.76132e-13" rpy="2.06672e-15 -1.15513e-14 2.53967e-15"/>
      <geometry>
        <mesh filename="package://open_duck_mini_description/meshes/trunk_bottom.stl"/>
      </geometry>
      <material name="trunk_bottom_material">
        <color rgba="0.180392 0.180392 0.180392 1.0"/>
      </material>
    </visual>
    <collision>
      <origin xyz="6.93285e-16 4.28849e-16 3.76132e-13" rpy="2.06672e-15 -1.15513e-14 2.53967e-15"/>
      <geometry>
        <mesh filename="package://open_duck_mini_description/meshes/trunk_bottom.stl"/>
      </geometry>
    </collision>
    <!-- Part trunk_top_back -->
    <visual>
      <origin xyz="6.91563e-16 4.29657e-16 3.76131e-13" rpy="2.06672e-15 -1.15513e-14 2.53967e-15"/>
      <geometry>
        <mesh filename="package://open_duck_mini_description/meshes/trunk_top_back.stl"/>
      </geometry>
      <material name="trunk_top_back_material">
        <color rgba="0.180392 0.180392 0.180392 1.0"/>
      </material>
    </visual>
    <collision>
      <origin xyz="6.91563e-16 4.29657e-16 3.76131e-13" rpy="2.06672e-15 -1.15513e-14 2.53967e-15"/>
      <geometry>
        <mesh filename="package://open_duck_mini_description/meshes/trunk_top_back.stl"/>
      </geometry>
    </collision>
    <!-- Part bno055 -->
    <visual>
      <origin xyz="-0.08692 0.00079 0.0417909" rpy="2.06672e-15 -1.15513e-14 2.53967e-15"/>
      <geometry>
        <mesh filename="package://open_duck_mini_description/meshes/bno055.stl"/>
      </geometry>
      <material name="bno055_material">
        <color rgba="0.615686 0.811765 0.929412 1.0"/>
      </material>
    </visual>
    <collision>
      <origin xyz="-0.08692 0.00079 0.0417909" rpy="2.06672e-15 -1.15513e-14 2.53967e-15"/>
      <geometry>
        <mesh filename="package://open_duck_mini_description/meshes/bno055.stl"/>
      </geometry>
    </collision>
    <!-- Part roll_bearing -->
    <visual>
      <origin xyz="-0.019 2.36075e-16 0.0648909" rpy="2.06672e-15 -1.15513e-14 2.53967e-15"/>
      <geometry>
        <mesh filename="package://open_duck_mini_description/meshes/roll_bearing.stl"/>
      </geometry>
      <material name="roll_bearing_material">
        <color rgba="0.6 0.6 0.6 1.0"/>
      </material>
    </visual>
    <collision>
      <origin xyz="-0.019 2.36075e-16 0.0648909" rpy="2.06672e-15 -1.15513e-14 2.53967e-15"/>
      <geometry>
        <mesh filename="package://open_duck_mini_description/meshes/roll_bearing.stl"/>
      </geometry>
    </collision>
    <!-- Part trunk_top_front -->
    <visual>
      <origin xyz="6.93285e-16 4.28849e-16 3.76132e-13" rpy="2.06672e-15 -1.15513e-14 2.53967e-15"/>
      <geometry>
        <mesh filename="package://open_duck_mini_description/meshes/trunk_top_front.stl"/>
      </geometry>
      <material name="trunk_top_front_material">
        <color rgba="0.180392 0.180392 0.180392 1.0"/>
      </material>
    </visual>
    <collision>
      <origin xyz="6.93285e-16 4.28849e-16 3.76132e-13" rpy="2.06672e-15 -1.15513e-14 2.53967e-15"/>
      <geometry>
        <mesh filename="package://open_duck_mini_description/meshes/trunk_top_front.stl"/>
      </geometry>
    </collision>
    <!-- Part rpi_zero_bridge_top -->
    <visual>
      <origin xyz="0.003 4.42743e-16 3.7616e-13" rpy="2.36244e-15 -1.15513e-14 2.53967e-15"/>
      <geometry>
        <mesh filename="package://open_duck_mini_description/meshes/rpi_zero_bridge_top.stl"/>
      </geometry>
      <material name="rpi_zero_bridge_top_material">
        <color rgba="0.627451 0.627451 0.643137 1.0"/>
      </material>
    </visual>
    <collision>
      <origin xyz="0.003 4.42743e-16 3.7616e-13" rpy="2.36244e-15 -1.15513e-14 2.53967e-15"/>
      <geometry>
        <mesh filename="package://open_duck_mini_description/meshes/rpi_zero_bridge_top.stl"/>
      </geometry>
    </collision>
    <!-- Part rpi_zero_bridge_bottom -->
    <visual>
      <origin xyz="0.003 4.39274e-16 3.76162e-13" rpy="2.36244e-15 -1.15513e-14 2.62734e-15"/>
      <geometry>
        <mesh filename="package://open_duck_mini_description/meshes/rpi_zero_bridge_bottom.stl"/>
      </geometry>
      <material name="rpi_zero_bridge_bottom_material">
        <color rgba="0.501961 0.501961 0.501961 1.0"/>
      </material>
    </visual>
    <collision>
      <origin xyz="0.003 4.39274e-16 3.76162e-13" rpy="2.36244e-15 -1.15513e-14 2.62734e-15"/>
      <geometry>
        <mesh filename="package://open_duck_mini_description/meshes/rpi_zero_bridge_bottom.stl"/>
      </geometry>
    </collision>
    <!-- Part board -->
    <visual>
      <origin xyz="-0.06349 0.0165 0.0603909" rpy="-2.22182e-15 1.11561e-14 -3.14159"/>
      <geometry>
        <mesh filename="package://open_duck_mini_description/meshes/board.stl"/>
      </geometry>
      <material name="board_material">
        <color rgba="0 0.501961 0 1.0"/>
      </material>
    </visual>
    <collision>
      <origin xyz="-0.06349 0.0165 0.0603909" rpy="-2.22182e-15 1.11561e-14 -3.14159"/>
      <geometry>
        <mesh filename="package://open_duck_mini_description/meshes/board.stl"/>
      </geometry>
    </collision>
    <!-- Part rpi_and_5v_reg_mount -->
    <visual>
      <origin xyz="6.93285e-16 4.34861e-16 3.76129e-13" rpy="2.36244e-15 -1.15513e-14 2.53967e-15"/>
      <geometry>
        <mesh filename="package://open_duck_mini_description/meshes/rpi_and_5v_reg_mount.stl"/>
      </geometry>
      <material name="rpi_and_5v_reg_mount_material">
        <color rgba="0.627451 0.627451 0.643137 1.0"/>
      </material>
    </visual>
    <collision>
      <origin xyz="6.93285e-16 4.34861e-16 3.76129e-13" rpy="2.36244e-15 -1.15513e-14 2.53967e-15"/>
      <geometry>
        <mesh filename="package://open_duck_mini_description/meshes/rpi_and_5v_reg_mount.stl"/>
      </geometry>
    </collision>
    <!-- Part roll_bearing_2 -->
    <visual>
      <origin xyz="-0.019 -0.07 0.0648909" rpy="2.06672e-15 -1.15513e-14 2.53967e-15"/>
      <geometry>
        <mesh filename="package://open_duck_mini_description/meshes/roll_bearing.stl"/>
      </geometry>
      <material name="roll_bearing_2_material">
        <color rgba="0.6 0.6 0.6 1.0"/>
      </material>
    </visual>
    <collision>
      <origin xyz="-0.019 -0.07 0.0648909" rpy="2.06672e-15 -1.15513e-14 2.53967e-15"/>
      <geometry>
        <mesh filename="package://open_duck_mini_description/meshes/roll_bearing.stl"/>
      </geometry>
    </collision>
    <!-- Part cell -->
    <visual>
      <origin xyz="-0.120984 -0.010299 0.0793134" rpy="-3.14159 7.17506e-17 2.19131"/>
      <geometry>
        <mesh filename="package://open_duck_mini_description/meshes/cell.stl"/>
      </geometry>
      <material name="cell_material">
        <color rgba="0.615686 0.811765 0.929412 1.0"/>
      </material>
    </visual>
    <collision>
      <origin xyz="-0.120984 -0.010299 0.0793134" rpy="-3.14159 7.17506e-17 2.19131"/>
      <geometry>
        <mesh filename="package://open_duck_mini_description/meshes/cell.stl"/>
      </geometry>
    </collision>
    <!-- Part holder -->
    <visual>
      <origin xyz="-0.130984 -0.0633235 0.0457549" rpy="-2.53967e-15 1.5708 0"/>
      <geometry>
        <mesh filename="package://open_duck_mini_description/meshes/holder.stl"/>
      </geometry>
      <material name="holder_material">
        <color rgba="0.647059 0.647059 0.647059 1.0"/>
      </material>
    </visual>
    <collision>
      <origin xyz="-0.130984 -0.0633235 0.0457549" rpy="-2.53967e-15 1.5708 0"/>
      <geometry>
        <mesh filename="package://open_duck_mini_description/meshes/holder.stl"/>
      </geometry>
    </collision>
    <!-- Part cell_2 -->
    <visual>
      <origin xyz="-0.120984 0.010701 0.0143134" rpy="-1.27503e-14 -2.0017e-14 0.750265"/>
      <geometry>
        <mesh filename="package://open_duck_mini_description/meshes/cell.stl"/>
      </geometry>
      <material name="cell_2_material">
        <color rgba="0.615686 0.811765 0.929412 1.0"/>
      </material>
    </visual>
    <collision>
      <origin xyz="-0.120984 0.010701 0.0143134" rpy="-1.27503e-14 -2.0017e-14 0.750265"/>
      <geometry>
        <mesh filename="package://open_duck_mini_description/meshes/cell.stl"/>
      </geometry>
    </collision>
    <!-- Part wj_wk00_0123middlecase_56 -->
    <visual>
      <origin xyz="0.001 0.0097 0.0645009" rpy="-2.62734e-15 1.5708 0"/>
      <geometry>
        <mesh filename="package://open_duck_mini_description/meshes/wj_wk00_0123middlecase_56.stl"/>
      </geometry>
      <material name="wj_wk00_0123middlecase_56_material">
        <color rgba="0.247059 0.243137 0.243137 1.0"/>
      </material>
    </visual>
    <collision>
      <origin xyz="0.001 0.0097 0.0645009" rpy="-2.62734e-15 1.5708 0"/>
      <geometry>
        <mesh filename="package://open_duck_mini_description/meshes/wj_wk00_0123middlecase_56.stl"/>
      </geometry>
    </collision>
    <!-- Part drive_palonier -->
    <visual>
      <origin xyz="0.001 0.0097 0.0645009" rpy="-2.62734e-15 1.5708 0"/>
      <geometry>
        <mesh filename="package://open_duck_mini_description/meshes/drive_palonier.stl"/>
      </geometry>
      <material name="drive_palonier_material">
        <color rgba="0.623529 0.666667 0.701961 1.0"/>
      </material>
    </visual>
    <collision>
      <origin xyz="0.001 0.0097 0.0645009" rpy="-2.62734e-15 1.5708 0"/>
      <geometry>
        <mesh filename="package://open_duck_mini_description/meshes/drive_palonier.stl"/>
      </geometry>
    </collision>
    <!-- Part wj_wk00_0124bottomcase_45 -->
    <visual>
      <origin xyz="0.001 0.0097 0.0645009" rpy="-2.62734e-15 1.5708 0"/>
      <geometry>
        <mesh filename="package://open_duck_mini_description/meshes/wj_wk00_0124bottomcase_45.stl"/>
      </geometry>
      <material name="wj_wk00_0124bottomcase_45_material">
        <color rgba="0.247059 0.243137 0.243137 1.0"/>
      </material>
    </visual>
    <collision>
      <origin xyz="0.001 0.0097 0.0645009" rpy="-2.62734e-15 1.5708 0"/>
      <geometry>
        <mesh filename="package://open_duck_mini_description/meshes/wj_wk00_0124bottomcase_45.stl"/>
      </geometry>
    </collision>
    <!-- Part wj_wk00_0122topcabinetcase_95 -->
    <visual>
      <origin xyz="0.001 0.0097 0.0645009" rpy="-2.62734e-15 1.5708 0"/>
      <geometry>
        <mesh filename="package://open_duck_mini_description/meshes/wj_wk00_0122topcabinetcase_95.stl"/>
      </geometry>
      <material name="wj_wk00_0122topcabinetcase_95_material">
        <color rgba="0.247059 0.243137 0.243137 1.0"/>
      </material>
    </visual>
    <collision>
      <origin xyz="0.001 0.0097 0.0645009" rpy="-2.62734e-15 1.5708 0"/>
      <geometry>
        <mesh filename="package://open_duck_mini_description/meshes/wj_wk00_0122topcabinetcase_95.stl"/>
      </geometry>
    </collision>
    <!-- Part passive_palonier -->
    <visual>
      <origin xyz="0.001 0.0126 0.0645009" rpy="-2.62734e-15 1.5708 0"/>
      <geometry>
        <mesh filename="package://open_duck_mini_description/meshes/passive_palonier.stl"/>
      </geometry>
      <material name="passive_palonier_material">
        <color rgba="0.623529 0.666667 0.701961 1.0"/>
      </material>
    </visual>
    <collision>
      <origin xyz="0.001 0.0126 0.0645009" rpy="-2.62734e-15 1.5708 0"/>
      <geometry>
        <mesh filename="package://open_duck_mini_description/meshes/passive_palonier.stl"/>
      </geometry>
    </collision>
    <!-- Part wj_wk00_0123middlecase_56_2 -->
    <visual>
      <origin xyz="-0.0445 -0.035 0.0551909" rpy="-1.5708 1.15513e-14 -3.14159"/>
      <geometry>
        <mesh filename="package://open_duck_mini_description/meshes/wj_wk00_0123middlecase_56.stl"/>
      </geometry>
      <material name="wj_wk00_0123middlecase_56_2_material">
        <color rgba="0.247059 0.243137 0.243137 1.0"/>
      </material>
    </visual>
    <collision>
      <origin xyz="-0.0445 -0.035 0.0551909" rpy="-1.5708 1.15513e-14 -3.14159"/>
      <geometry>
        <mesh filename="package://open_duck_mini_description/meshes/wj_wk00_0123middlecase_56.stl"/>
      </geometry>
    </collision>
    <!-- Part drive_palonier_2 -->
    <visual>
      <origin xyz="-0.0445 -0.035 0.0551909" rpy="-1.5708 1.15513e-14 -3.14159"/>
      <geometry>
        <mesh filename="package://open_duck_mini_description/meshes/drive_palonier.stl"/>
      </geometry>
      <material name="drive_palonier_2_material">
        <color rgba="0.623529 0.666667 0.701961 1.0"/>
      </material>
    </visual>
    <collision>
      <origin xyz="-0.0445 -0.035 0.0551909" rpy="-1.5708 1.15513e-14 -3.14159"/>
      <geometry>
        <mesh filename="package://open_duck_mini_description/meshes/drive_palonier.stl"/>
      </geometry>
    </collision>
    <!-- Part wj_wk00_0124bottomcase_45_2 -->
    <visual>
      <origin xyz="-0.0445 -0.035 0.0551909" rpy="-1.5708 1.15513e-14 -3.14159"/>
      <geometry>
        <mesh filename="package://open_duck_mini_description/meshes/wj_wk00_0124bottomcase_45.stl"/>
      </geometry>
      <material name="wj_wk00_0124bottomcase_45_2_material">
        <color rgba="0.247059 0.243137 0.243137 1.0"/>
      </material>
    </visual>
    <collision>
      <origin xyz="-0.0445 -0.035 0.0551909" rpy="-1.5708 1.15513e-14 -3.14159"/>
      <geometry>
        <mesh filename="package://open_duck_mini_description/meshes/wj_wk00_0124bottomcase_45.stl"/>
      </geometry>
    </collision>
    <!-- Part wj_wk00_0122topcabinetcase_95_2 -->
    <visual>
      <origin xyz="-0.0445 -0.035 0.0551909" rpy="-1.5708 1.15513e-14 -3.14159"/>
      <geometry>
        <mesh filename="package://open_duck_mini_description/meshes/wj_wk00_0122topcabinetcase_95.stl"/>
      </geometry>
      <material name="wj_wk00_0122topcabinetcase_95_2_material">
        <color rgba="0.247059 0.243137 0.243137 1.0"/>
      </material>
    </visual>
    <collision>
      <origin xyz="-0.0445 -0.035 0.0551909" rpy="-1.5708 1.15513e-14 -3.14159"/>
      <geometry>
        <mesh filename="package://open_duck_mini_description/meshes/wj_wk00_0122topcabinetcase_95.stl"/>
      </geometry>
    </collision>
    <!-- Part passive_palonier_2 -->
    <visual>
      <origin xyz="-0.0445 -0.035 0.0522909" rpy="-1.5708 1.15513e-14 -3.14159"/>
      <geometry>
        <mesh filename="package://open_duck_mini_description/meshes/passive_palonier.stl"/>
      </geometry>
      <material name="passive_palonier_2_material">
        <color rgba="0.623529 0.666667 0.701961 1.0"/>
      </material>
    </visual>
    <collision>
      <origin xyz="-0.0445 -0.035 0.0522909" rpy="-1.5708 1.15513e-14 -3.14159"/>
      <geometry>
        <mesh filename="package://open_duck_mini_description/meshes/passive_palonier.stl"/>
      </geometry>
    </collision>
    <!-- Part wj_wk00_0123middlecase_56_3 -->
    <visual>
      <origin xyz="-0.0445 0.035 0.0551909" rpy="-1.5708 1.15513e-14 -3.14159"/>
      <geometry>
        <mesh filename="package://open_duck_mini_description/meshes/wj_wk00_0123middlecase_56.stl"/>
      </geometry>
      <material name="wj_wk00_0123middlecase_56_3_material">
        <color rgba="0.247059 0.243137 0.243137 1.0"/>
      </material>
    </visual>
    <collision>
      <origin xyz="-0.0445 0.035 0.0551909" rpy="-1.5708 1.15513e-14 -3.14159"/>
      <geometry>
        <mesh filename="package://open_duck_mini_description/meshes/wj_wk00_0123middlecase_56.stl"/>
      </geometry>
    </collision>
    <!-- Part drive_palonier_3 -->
    <visual>
      <origin xyz="-0.0445 0.035 0.0551909" rpy="-1.5708 1.15513e-14 -3.14159"/>
      <geometry>
        <mesh filename="package://open_duck_mini_description/meshes/drive_palonier.stl"/>
      </geometry>
      <material name="drive_palonier_3_material">
        <color rgba="0.623529 0.666667 0.701961 1.0"/>
      </material>
    </visual>
    <collision>
      <origin xyz="-0.0445 0.035 0.0551909" rpy="-1.5708 1.15513e-14 -3.14159"/>
      <geometry>
        <mesh filename="package://open_duck_mini_description/meshes/drive_palonier.stl"/>
      </geometry>
    </collision>
    <!-- Part wj_wk00_0124bottomcase_45_3 -->
    <visual>
      <origin xyz="-0.0445 0.035 0.0551909" rpy="-1.5708 1.15513e-14 -3.14159"/>
      <geometry>
        <mesh filename="package://open_duck_mini_description/meshes/wj_wk00_0124bottomcase_45.stl"/>
      </geometry>
      <material name="wj_wk00_0124bottomcase_45_3_material">
        <color rgba="0.247059 0.243137 0.243137 1.0"/>
      </material>
    </visual>
    <collision>
      <origin xyz="-0.0445 0.035 0.0551909" rpy="-1.5708 1.15513e-14 -3.14159"/>
      <geometry>
        <mesh filename="package://open_duck_mini_description/meshes/wj_wk00_0124bottomcase_45.stl"/>
      </geometry>
    </collision>
    <!-- Part wj_wk00_0122topcabinetcase_95_3 -->
    <visual>
      <origin xyz="-0.0445 0.035 0.0551909" rpy="-1.5708 1.15513e-14 -3.14159"/>
      <geometry>
        <mesh filename="package://open_duck_mini_description/meshes/wj_wk00_0122topcabinetcase_95.stl"/>
      </geometry>
      <material name="wj_wk00_0122topcabinetcase_95_3_material">
        <color rgba="0.247059 0.243137 0.243137 1.0"/>
      </material>
    </visual>
    <collision>
      <origin xyz="-0.0445 0.035 0.0551909" rpy="-1.5708 1.15513e-14 -3.14159"/>
      <geometry>
        <mesh filename="package://open_duck_mini_description/meshes/wj_wk00_0122topcabinetcase_95.stl"/>
      </geometry>
    </collision>
    <!-- Part passive_palonier_3 -->
    <visual>
      <origin xyz="-0.0445 0.035 0.0522909" rpy="-1.5708 1.15513e-14 -3.14159"/>
      <geometry>
        <mesh filename="package://open_duck_mini_description/meshes/passive_palonier.stl"/>
      </geometry>
      <material name="passive_palonier_3_material">
        <color rgba="0.623529 0.666667 0.701961 1.0"/>
      </material>
    </visual>
    <collision>
      <origin xyz="-0.0445 0.035 0.0522909" rpy="-1.5708 1.15513e-14 -3.14159"/>
      <geometry>
        <mesh filename="package://open_duck_mini_description/meshes/passive_palonier.stl"/>
      </geometry>
    </collision>
  </link>
  <!-- Frame imu (dummy link + fixed joint) -->
  <link name="imu">
    <origin xyz="0 0 0" rpy="0 -0 0"/>
    <inertial>
      <origin xyz="0 0 0" rpy="0 0 0"/>
      <mass value="1e-9"/>
      <inertia ixx="0" ixy="0" ixz="0" iyy="0" iyz="0" izz="0"/>
    </inertial>
  </link>
  <joint name="imu_frame" type="fixed">
    <origin xyz="-0.08692 0.00079 0.0422909" rpy="1.26181e-15 -1.15513e-14 2.53967e-15"/>
    <parent link="trunk_assembly"/>
    <child link="imu"/>
    <axis xyz="0 0 0"/>
  </joint>
  <!-- Link hip_roll_assembly -->
  <link name="hip_roll_assembly">
    <inertial>
      <origin xyz="0.000795081 -5.46541e-06 -0.03306" rpy="0 0 0"/>
      <mass value="0.06648"/>
      <inertia ixx="2.44411e-05" ixy="2.35658e-09" ixz="-3.81059e-07" iyy="2.81818e-05" iyz="-7.50036e-09" izz="1.42687e-05"/>
    </inertial>
    <!-- Part roll_motor_bottom -->
    <visual>
      <origin xyz="-3.29597e-16 -0.035 0.01905" rpy="-8.76998e-16 7.09142e-16 -5.55112e-16"/>
      <geometry>
        <mesh filename="package://open_duck_mini_description/meshes/roll_motor_bottom.stl"/>
      </geometry>
      <material name="roll_motor_bottom_material">
        <color rgba="0.647059 0.647059 0.647059 1.0"/>
      </material>
    </visual>
    <collision>
      <origin xyz="-3.29597e-16 -0.035 0.01905" rpy="-8.76998e-16 7.09142e-16 -5.55112e-16"/>
      <geometry>
        <mesh filename="package://open_duck_mini_description/meshes/roll_motor_bottom.stl"/>
      </geometry>
    </collision>
    <!-- Part roll_motor_top -->
    <visual>
      <origin xyz="3.46945e-18 -0.035 0.01905" rpy="-1.18789e-31 2.48714e-31 6.36021e-33"/>
      <geometry>
        <mesh filename="package://open_duck_mini_description/meshes/roll_motor_top.stl"/>
      </geometry>
      <material name="roll_motor_top_material">
        <color rgba="0.901961 0.901961 0.901961 1.0"/>
      </material>
    </visual>
    <collision>
      <origin xyz="3.46945e-18 -0.035 0.01905" rpy="-1.18789e-31 2.48714e-31 6.36021e-33"/>
      <geometry>
        <mesh filename="package://open_duck_mini_description/meshes/roll_motor_top.stl"/>
      </geometry>
    </collision>
    <!-- Part wj_wk00_0123middlecase_56_4 -->
    <visual>
      <origin xyz="0.0096 1.68546e-14 -0.020515" rpy="-1.5708 -1.5708 0"/>
      <geometry>
        <mesh filename="package://open_duck_mini_description/meshes/wj_wk00_0123middlecase_56.stl"/>
      </geometry>
      <material name="wj_wk00_0123middlecase_56_4_material">
        <color rgba="0.247059 0.243137 0.243137 1.0"/>
      </material>
    </visual>
    <collision>
      <origin xyz="0.0096 1.68546e-14 -0.020515" rpy="-1.5708 -1.5708 0"/>
      <geometry>
        <mesh filename="package://open_duck_mini_description/meshes/wj_wk00_0123middlecase_56.stl"/>
      </geometry>
    </collision>
    <!-- Part drive_palonier_4 -->
    <visual>
      <origin xyz="0.0096 1.68546e-14 -0.020515" rpy="-1.5708 -1.5708 0"/>
      <geometry>
        <mesh filename="package://open_duck_mini_description/meshes/drive_palonier.stl"/>
      </geometry>
      <material name="drive_palonier_4_material">
        <color rgba="0.623529 0.666667 0.701961 1.0"/>
      </material>
    </visual>
    <collision>
      <origin xyz="0.0096 1.68546e-14 -0.020515" rpy="-1.5708 -1.5708 0"/>
      <geometry>
        <mesh filename="package://open_duck_mini_description/meshes/drive_palonier.stl"/>
      </geometry>
    </collision>
    <!-- Part wj_wk00_0124bottomcase_45_4 -->
    <visual>
      <origin xyz="0.0096 1.68546e-14 -0.020515" rpy="-1.5708 -1.5708 0"/>
      <geometry>
        <mesh filename="package://open_duck_mini_description/meshes/wj_wk00_0124bottomcase_45.stl"/>
      </geometry>
      <material name="wj_wk00_0124bottomcase_45_4_material">
        <color rgba="0.247059 0.243137 0.243137 1.0"/>
      </material>
    </visual>
    <collision>
      <origin xyz="0.0096 1.68546e-14 -0.020515" rpy="-1.5708 -1.5708 0"/>
      <geometry>
        <mesh filename="package://open_duck_mini_description/meshes/wj_wk00_0124bottomcase_45.stl"/>
      </geometry>
    </collision>
    <!-- Part wj_wk00_0122topcabinetcase_95_4 -->
    <visual>
      <origin xyz="0.0096 1.68546e-14 -0.020515" rpy="-1.5708 -1.5708 0"/>
      <geometry>
        <mesh filename="package://open_duck_mini_description/meshes/wj_wk00_0122topcabinetcase_95.stl"/>
      </geometry>
      <material name="wj_wk00_0122topcabinetcase_95_4_material">
        <color rgba="0.247059 0.243137 0.243137 1.0"/>
      </material>
    </visual>
    <collision>
      <origin xyz="0.0096 1.68546e-14 -0.020515" rpy="-1.5708 -1.5708 0"/>
      <geometry>
        <mesh filename="package://open_duck_mini_description/meshes/wj_wk00_0122topcabinetcase_95.stl"/>
      </geometry>
    </collision>
    <!-- Part passive_palonier_4 -->
    <visual>
      <origin xyz="0.0125 1.54529e-14 -0.020515" rpy="-1.5708 -1.5708 0"/>
      <geometry>
        <mesh filename="package://open_duck_mini_description/meshes/passive_palonier.stl"/>
      </geometry>
      <material name="passive_palonier_4_material">
        <color rgba="0.623529 0.666667 0.701961 1.0"/>
      </material>
    </visual>
    <collision>
      <origin xyz="0.0125 1.54529e-14 -0.020515" rpy="-1.5708 -1.5708 0"/>
      <geometry>
        <mesh filename="package://open_duck_mini_description/meshes/passive_palonier.stl"/>
      </geometry>
    </collision>
  </link>
  <!-- Link left_roll_to_pitch_assembly -->
  <link name="left_roll_to_pitch_assembly">
    <inertial>
      <origin xyz="0.0507497 -0.000407512 0.0204377" rpy="0 0 0"/>
      <mass value="0.07516"/>
      <inertia ixx="2.52682e-05" ixy="1.22744e-07" ixz="-7.32857e-07" iyy="4.15738e-05" iyz="-1.05692e-07" izz="2.82869e-05"/>
    </inertial>
    <!-- Part left_roll_to_pitch -->
    <visual>
      <origin xyz="-0.035 -0.065 0.01905" rpy="1.5708 1.5708 0"/>
      <geometry>
        <mesh filename="package://open_duck_mini_description/meshes/left_roll_to_pitch.stl"/>
      </geometry>
      <material name="left_roll_to_pitch_material">
        <color rgba="0.909804 0.572549 0.164706 1.0"/>
      </material>
    </visual>
    <collision>
      <origin xyz="-0.035 -0.065 0.01905" rpy="1.5708 1.5708 0"/>
      <geometry>
        <mesh filename="package://open_duck_mini_description/meshes/left_roll_to_pitch.stl"/>
      </geometry>
    </collision>
    <!-- Part wj_wk00_0123middlecase_56_5 -->
    <visual>
      <origin xyz="0.0647 -1.24141e-17 0.00961" rpy="1.5708 1.5708 0"/>
      <geometry>
        <mesh filename="package://open_duck_mini_description/meshes/wj_wk00_0123middlecase_56.stl"/>
      </geometry>
      <material name="wj_wk00_0123middlecase_56_5_material">
        <color rgba="0.247059 0.243137 0.243137 1.0"/>
      </material>
    </visual>
    <collision>
      <origin xyz="0.0647 -1.24141e-17 0.00961" rpy="1.5708 1.5708 0"/>
      <geometry>
        <mesh filename="package://open_duck_mini_description/meshes/wj_wk00_0123middlecase_56.stl"/>
      </geometry>
    </collision>
    <!-- Part drive_palonier_5 -->
    <visual>
      <origin xyz="0.0647 -1.24141e-17 0.00961" rpy="1.5708 1.5708 0"/>
      <geometry>
        <mesh filename="package://open_duck_mini_description/meshes/drive_palonier.stl"/>
      </geometry>
      <material name="drive_palonier_5_material">
        <color rgba="0.623529 0.666667 0.701961 1.0"/>
      </material>
    </visual>
    <collision>
      <origin xyz="0.0647 -1.24141e-17 0.00961" rpy="1.5708 1.5708 0"/>
      <geometry>
        <mesh filename="package://open_duck_mini_description/meshes/drive_palonier.stl"/>
      </geometry>
    </collision>
    <!-- Part wj_wk00_0124bottomcase_45_5 -->
    <visual>
      <origin xyz="0.0647 -1.24141e-17 0.00961" rpy="1.5708 1.5708 0"/>
      <geometry>
        <mesh filename="package://open_duck_mini_description/meshes/wj_wk00_0124bottomcase_45.stl"/>
      </geometry>
      <material name="wj_wk00_0124bottomcase_45_5_material">
        <color rgba="0.247059 0.243137 0.243137 1.0"/>
      </material>
    </visual>
    <collision>
      <origin xyz="0.0647 -1.24141e-17 0.00961" rpy="1.5708 1.5708 0"/>
      <geometry>
        <mesh filename="package://open_duck_mini_description/meshes/wj_wk00_0124bottomcase_45.stl"/>
      </geometry>
    </collision>
    <!-- Part wj_wk00_0122topcabinetcase_95_5 -->
    <visual>
      <origin xyz="0.0647 -1.24141e-17 0.00961" rpy="1.5708 1.5708 0"/>
      <geometry>
        <mesh filename="package://open_duck_mini_description/meshes/wj_wk00_0122topcabinetcase_95.stl"/>
      </geometry>
      <material name="wj_wk00_0122topcabinetcase_95_5_material">
        <color rgba="0.247059 0.243137 0.243137 1.0"/>
      </material>
    </visual>
    <collision>
      <origin xyz="0.0647 -1.24141e-17 0.00961" rpy="1.5708 1.5708 0"/>
      <geometry>
        <mesh filename="package://open_duck_mini_description/meshes/wj_wk00_0122topcabinetcase_95.stl"/>
      </geometry>
    </collision>
    <!-- Part passive_palonier_5 -->
    <visual>
      <origin xyz="0.0676 5.64978e-16 0.00961" rpy="1.5708 1.5708 0"/>
      <geometry>
        <mesh filename="package://open_duck_mini_description/meshes/passive_palonier.stl"/>
      </geometry>
      <material name="passive_palonier_5_material">
        <color rgba="0.623529 0.666667 0.701961 1.0"/>
      </material>
    </visual>
    <collision>
      <origin xyz="0.0676 5.64978e-16 0.00961" rpy="1.5708 1.5708 0"/>
      <geometry>
        <mesh filename="package://open_duck_mini_description/meshes/passive_palonier.stl"/>
      </geometry>
    </collision>
  </link>
  <!-- Link knee_and_ankle_assembly -->
  <link name="knee_and_ankle_assembly">
    <inertial>
      <origin xyz="0.00288653 -0.0443678 0.00916586" rpy="0 0 0"/>
      <mass value="0.118109"/>
      <inertia ixx="0.000184902" ixy="-1.81352e-05" ixz="4.64073e-06" iyy="7.07811e-05" iyz="1.64734e-05" izz="0.000188981"/>
    </inertial>
    <!-- Part leg_spacer -->
    <visual>
      <origin xyz="0.01606 0.14365 0.10925" rpy="-1.5708 1.90751e-28 1.66533e-16"/>
      <geometry>
        <mesh filename="package://open_duck_mini_description/meshes/leg_spacer.stl"/>
      </geometry>
      <material name="leg_spacer_material">
        <color rgba="0.647059 0.647059 0.647059 1.0"/>
      </material>
    </visual>
    <collision>
      <origin xyz="0.01606 0.14365 0.10925" rpy="-1.5708 1.90751e-28 1.66533e-16"/>
      <geometry>
        <mesh filename="package://open_duck_mini_description/meshes/leg_spacer.stl"/>
      </geometry>
    </collision>
    <!-- Part left_knee_to_ankle_right_sheet -->
    <visual>
      <origin xyz="0.01606 0.14365 0.10915" rpy="-1.5708 1.52298e-28 5.55112e-17"/>
      <geometry>
        <mesh filename="package://open_duck_mini_description/meshes/left_knee_to_ankle_right_sheet.stl"/>
      </geometry>
      <material name="left_knee_to_ankle_right_sheet_material">
        <color rgba="0.223529 0.219608 0.219608 1.0"/>
      </material>
    </visual>
    <collision>
      <origin xyz="0.01606 0.14365 0.10915" rpy="-1.5708 1.52298e-28 5.55112e-17"/>
      <geometry>
        <mesh filename="package://open_duck_mini_description/meshes/left_knee_to_ankle_right_sheet.stl"/>
      </geometry>
    </collision>
    <!-- Part left_knee_to_ankle_left_sheet -->
    <visual>
      <origin xyz="0.01606 0.14365 0.10915" rpy="-1.5708 6.85451e-30 -5.72329e-29"/>
      <geometry>
        <mesh filename="package://open_duck_mini_description/meshes/left_knee_to_ankle_left_sheet.stl"/>
      </geometry>
      <material name="left_knee_to_ankle_left_sheet_material">
        <color rgba="0.223529 0.219608 0.219608 1.0"/>
      </material>
    </visual>
    <collision>
      <origin xyz="0.01606 0.14365 0.10915" rpy="-1.5708 6.85451e-30 -5.72329e-29"/>
      <geometry>
        <mesh filename="package://open_duck_mini_description/meshes/left_knee_to_ankle_left_sheet.stl"/>
      </geometry>
    </collision>
    <!-- Part left_upper_cable_guide -->
    <visual>
      <origin xyz="0.03506 7.40612e-05 0.109134" rpy="-1.5708 6.85451e-30 -5.72329e-29"/>
      <geometry>
        <mesh filename="package://open_duck_mini_description/meshes/left_upper_cable_guide.stl"/>
      </geometry>
      <material name="left_upper_cable_guide_material">
        <color rgba="1 1 1 1.0"/>
      </material>
    </visual>
    <collision>
      <origin xyz="0.03506 7.40612e-05 0.109134" rpy="-1.5708 6.85451e-30 -5.72329e-29"/>
      <geometry>
        <mesh filename="package://open_duck_mini_description/meshes/left_upper_cable_guide.stl"/>
      </geometry>
    </collision>
    <!-- Part left_leg_cover -->
    <visual>
      <origin xyz="0.03506 7.40612e-05 0.10915" rpy="-1.5708 6.85451e-30 -5.72329e-29"/>
      <geometry>
        <mesh filename="package://open_duck_mini_description/meshes/left_leg_cover.stl"/>
      </geometry>
      <material name="left_leg_cover_material">
        <color rgba="1 1 1 1.0"/>
      </material>
    </visual>
    <collision>
      <origin xyz="0.03506 7.40612e-05 0.10915" rpy="-1.5708 6.85451e-30 -5.72329e-29"/>
      <geometry>
        <mesh filename="package://open_duck_mini_description/meshes/left_leg_cover.stl"/>
      </geometry>
    </collision>
    <!-- Part left_lower_cable_guide -->
    <visual>
      <origin xyz="0.03506 7.40612e-05 0.10915" rpy="-1.5708 6.85451e-30 -5.72329e-29"/>
      <geometry>
        <mesh filename="package://open_duck_mini_description/meshes/left_lower_cable_guide.stl"/>
      </geometry>
      <material name="left_lower_cable_guide_material">
        <color rgba="1 1 1 1.0"/>
      </material>
    </visual>
    <collision>
      <origin xyz="0.03506 7.40612e-05 0.10915" rpy="-1.5708 6.85451e-30 -5.72329e-29"/>
      <geometry>
        <mesh filename="package://open_duck_mini_description/meshes/left_lower_cable_guide.stl"/>
      </geometry>
    </collision>
    <!-- Part wj_wk00_0123middlecase_56_6 -->
    <visual>
      <origin xyz="2.84495e-16 -0.05315 0.00955" rpy="-1.5708 3.01566e-17 1.5708"/>
      <geometry>
        <mesh filename="package://open_duck_mini_description/meshes/wj_wk00_0123middlecase_56.stl"/>
      </geometry>
      <material name="wj_wk00_0123middlecase_56_6_material">
        <color rgba="0.247059 0.243137 0.243137 1.0"/>
      </material>
    </visual>
    <collision>
      <origin xyz="2.84495e-16 -0.05315 0.00955" rpy="-1.5708 3.01566e-17 1.5708"/>
      <geometry>
        <mesh filename="package://open_duck_mini_description/meshes/wj_wk00_0123middlecase_56.stl"/>
      </geometry>
    </collision>
    <!-- Part drive_palonier_6 -->
    <visual>
      <origin xyz="2.84495e-16 -0.05315 0.00955" rpy="-1.5708 3.01566e-17 1.5708"/>
      <geometry>
        <mesh filename="package://open_duck_mini_description/meshes/drive_palonier.stl"/>
      </geometry>
      <material name="drive_palonier_6_material">
        <color rgba="0.623529 0.666667 0.701961 1.0"/>
      </material>
    </visual>
    <collision>
      <origin xyz="2.84495e-16 -0.05315 0.00955" rpy="-1.5708 3.01566e-17 1.5708"/>
      <geometry>
        <mesh filename="package://open_duck_mini_description/meshes/drive_palonier.stl"/>
      </geometry>
    </collision>
    <!-- Part wj_wk00_0124bottomcase_45_6 -->
    <visual>
      <origin xyz="2.84495e-16 -0.05315 0.00955" rpy="-1.5708 3.01566e-17 1.5708"/>
      <geometry>
        <mesh filename="package://open_duck_mini_description/meshes/wj_wk00_0124bottomcase_45.stl"/>
      </geometry>
      <material name="wj_wk00_0124bottomcase_45_6_material">
        <color rgba="0.247059 0.243137 0.243137 1.0"/>
      </material>
    </visual>
    <collision>
      <origin xyz="2.84495e-16 -0.05315 0.00955" rpy="-1.5708 3.01566e-17 1.5708"/>
      <geometry>
        <mesh filename="package://open_duck_mini_description/meshes/wj_wk00_0124bottomcase_45.stl"/>
      </geometry>
    </collision>
    <!-- Part wj_wk00_0122topcabinetcase_95_6 -->
    <visual>
      <origin xyz="2.84495e-16 -0.05315 0.00955" rpy="-1.5708 3.01566e-17 1.5708"/>
      <geometry>
        <mesh filename="package://open_duck_mini_description/meshes/wj_wk00_0122topcabinetcase_95.stl"/>
      </geometry>
      <material name="wj_wk00_0122topcabinetcase_95_6_material">
        <color rgba="0.247059 0.243137 0.243137 1.0"/>
      </material>
    </visual>
    <collision>
      <origin xyz="2.84495e-16 -0.05315 0.00955" rpy="-1.5708 3.01566e-17 1.5708"/>
      <geometry>
        <mesh filename="package://open_duck_mini_description/meshes/wj_wk00_0122topcabinetcase_95.stl"/>
      </geometry>
    </collision>
    <!-- Part passive_palonier_6 -->
    <visual>
      <origin xyz="5.41234e-16 -0.05315 0.00665" rpy="-1.5708 3.01566e-17 1.5708"/>
      <geometry>
        <mesh filename="package://open_duck_mini_description/meshes/passive_palonier.stl"/>
      </geometry>
      <material name="passive_palonier_6_material">
        <color rgba="0.623529 0.666667 0.701961 1.0"/>
      </material>
    </visual>
    <collision>
      <origin xyz="5.41234e-16 -0.05315 0.00665" rpy="-1.5708 3.01566e-17 1.5708"/>
      <geometry>
        <mesh filename="package://open_duck_mini_description/meshes/passive_palonier.stl"/>
      </geometry>
    </collision>
  </link>
  <!-- Link knee_and_ankle_assembly_2 -->
  <link name="knee_and_ankle_assembly_2">
    <inertial>
      <origin xyz="5.01859e-06 -0.0577465 0.0181136" rpy="0 0 0"/>
      <mass value="0.07259"/>
      <inertia ixx="4.99575e-05" ixy="1.03817e-08" ixz="2.25175e-09" iyy="1.87273e-05" iyz="8.81049e-08" izz="4.23932e-05"/>
    </inertial>
    <!-- Part leg_spacer_2 -->
    <visual>
      <origin xyz="0.01606 0.14365 0.10925" rpy="-1.5708 -3.83419e-28 4.65921e-30"/>
      <geometry>
        <mesh filename="package://open_duck_mini_description/meshes/leg_spacer.stl"/>
      </geometry>
      <material name="leg_spacer_2_material">
        <color rgba="0.647059 0.647059 0.647059 1.0"/>
      </material>
    </visual>
    <collision>
      <origin xyz="0.01606 0.14365 0.10925" rpy="-1.5708 -3.83419e-28 4.65921e-30"/>
      <geometry>
        <mesh filename="package://open_duck_mini_description/meshes/leg_spacer.stl"/>
      </geometry>
    </collision>
    <!-- Part left_knee_to_ankle_right_sheet_2 -->
    <visual>
      <origin xyz="0.01606 0.14365 0.10915" rpy="-1.5708 1.21452e-28 4.65921e-30"/>
      <geometry>
        <mesh filename="package://open_duck_mini_description/meshes/left_knee_to_ankle_right_sheet.stl"/>
      </geometry>
      <material name="left_knee_to_ankle_right_sheet_2_material">
        <color rgba="0.223529 0.219608 0.219608 1.0"/>
      </material>
    </visual>
    <collision>
      <origin xyz="0.01606 0.14365 0.10915" rpy="-1.5708 1.21452e-28 4.65921e-30"/>
      <geometry>
        <mesh filename="package://open_duck_mini_description/meshes/left_knee_to_ankle_right_sheet.stl"/>
      </geometry>
    </collision>
    <!-- Part left_knee_to_ankle_left_sheet_2 -->
    <visual>
      <origin xyz="0.01606 0.14365 0.10915" rpy="-1.5708 -4.76575e-30 4.65921e-30"/>
      <geometry>
        <mesh filename="package://open_duck_mini_description/meshes/left_knee_to_ankle_left_sheet.stl"/>
      </geometry>
      <material name="left_knee_to_ankle_left_sheet_2_material">
        <color rgba="0.223529 0.219608 0.219608 1.0"/>
      </material>
    </visual>
    <collision>
      <origin xyz="0.01606 0.14365 0.10915" rpy="-1.5708 -4.76575e-30 4.65921e-30"/>
      <geometry>
        <mesh filename="package://open_duck_mini_description/meshes/left_knee_to_ankle_left_sheet.stl"/>
      </geometry>
    </collision>
    <!-- Part wj_wk00_0123middlecase_56_7 -->
    <visual>
      <origin xyz="-6.93889e-18 -0.05315 0.00955" rpy="-1.5708 2.7001e-17 1.5708"/>
      <geometry>
        <mesh filename="package://open_duck_mini_description/meshes/wj_wk00_0123middlecase_56.stl"/>
      </geometry>
      <material name="wj_wk00_0123middlecase_56_7_material">
        <color rgba="0.247059 0.243137 0.243137 1.0"/>
      </material>
    </visual>
    <collision>
      <origin xyz="-6.93889e-18 -0.05315 0.00955" rpy="-1.5708 2.7001e-17 1.5708"/>
      <geometry>
        <mesh filename="package://open_duck_mini_description/meshes/wj_wk00_0123middlecase_56.stl"/>
      </geometry>
    </collision>
    <!-- Part drive_palonier_7 -->
    <visual>
      <origin xyz="-6.93889e-18 -0.05315 0.00955" rpy="-1.5708 2.7001e-17 1.5708"/>
      <geometry>
        <mesh filename="package://open_duck_mini_description/meshes/drive_palonier.stl"/>
      </geometry>
      <material name="drive_palonier_7_material">
        <color rgba="0.623529 0.666667 0.701961 1.0"/>
      </material>
    </visual>
    <collision>
      <origin xyz="-6.93889e-18 -0.05315 0.00955" rpy="-1.5708 2.7001e-17 1.5708"/>
      <geometry>
        <mesh filename="package://open_duck_mini_description/meshes/drive_palonier.stl"/>
      </geometry>
    </collision>
    <!-- Part wj_wk00_0124bottomcase_45_7 -->
    <visual>
      <origin xyz="-6.93889e-18 -0.05315 0.00955" rpy="-1.5708 2.7001e-17 1.5708"/>
      <geometry>
        <mesh filename="package://open_duck_mini_description/meshes/wj_wk00_0124bottomcase_45.stl"/>
      </geometry>
      <material name="wj_wk00_0124bottomcase_45_7_material">
        <color rgba="0.247059 0.243137 0.243137 1.0"/>
      </material>
    </visual>
    <collision>
      <origin xyz="-6.93889e-18 -0.05315 0.00955" rpy="-1.5708 2.7001e-17 1.5708"/>
      <geometry>
        <mesh filename="package://open_duck_mini_description/meshes/wj_wk00_0124bottomcase_45.stl"/>
      </geometry>
    </collision>
    <!-- Part wj_wk00_0122topcabinetcase_95_7 -->
    <visual>
      <origin xyz="-6.93889e-18 -0.05315 0.00955" rpy="-1.5708 2.7001e-17 1.5708"/>
      <geometry>
        <mesh filename="package://open_duck_mini_description/meshes/wj_wk00_0122topcabinetcase_95.stl"/>
      </geometry>
      <material name="wj_wk00_0122topcabinetcase_95_7_material">
        <color rgba="0.247059 0.243137 0.243137 1.0"/>
      </material>
    </visual>
    <collision>
      <origin xyz="-6.93889e-18 -0.05315 0.00955" rpy="-1.5708 2.7001e-17 1.5708"/>
      <geometry>
        <mesh filename="package://open_duck_mini_description/meshes/wj_wk00_0122topcabinetcase_95.stl"/>
      </geometry>
    </collision>
    <!-- Part passive_palonier_7 -->
    <visual>
      <origin xyz="-6.73073e-16 -0.05315 0.00665" rpy="-1.5708 2.7001e-17 1.5708"/>
      <geometry>
        <mesh filename="package://open_duck_mini_description/meshes/passive_palonier.stl"/>
      </geometry>
      <material name="passive_palonier_7_material">
        <color rgba="0.623529 0.666667 0.701961 1.0"/>
      </material>
    </visual>
    <collision>
      <origin xyz="-6.73073e-16 -0.05315 0.00665" rpy="-1.5708 2.7001e-17 1.5708"/>
      <geometry>
        <mesh filename="package://open_duck_mini_description/meshes/passive_palonier.stl"/>
      </geometry>
    </collision>
  </link>
  <!-- Link foot_assembly -->
  <link name="foot_assembly">
    <inertial>
      <origin xyz="0.0110718 -0.0246608 0.0190626" rpy="0 0 0"/>
      <mass value="0.07524"/>
      <inertia ixx="1.87482e-05" ixy="1.58839e-06" ixz="-6.52354e-09" iyy="6.74427e-05" iyz="5.67391e-08" izz="6.061e-05"/>
    </inertial>
    <!-- Part foot_side -->
    <visual>
      <origin xyz="0.01606 0.2223 0.10905" rpy="-1.5708 -1.24631e-30 0"/>
      <geometry>
        <mesh filename="package://open_duck_mini_description/meshes/foot_side.stl"/>
      </geometry>
      <material name="foot_side_material">
        <color rgba="0.980392 0.713725 0.00392157 1.0"/>
      </material>
    </visual>
    <collision>
      <origin xyz="0.01606 0.2223 0.10905" rpy="-1.5708 -1.24631e-30 0"/>
      <geometry>
        <mesh filename="package://open_duck_mini_description/meshes/foot_side.stl"/>
      </geometry>
    </collision>
    <!-- Part foot_bottom_tpu -->
    <visual>
      <origin xyz="0.01656 0.2228 0.10955" rpy="-1.5708 -1.24631e-30 0"/>
      <geometry>
        <mesh filename="package://open_duck_mini_description/meshes/foot_bottom_tpu.stl"/>
      </geometry>
      <material name="foot_bottom_tpu_material">
        <color rgba="0.305882 0.298039 0.278431 1.0"/>
      </material>
    </visual>
    <collision>
      <origin xyz="0.01656 0.2228 0.10955" rpy="-1.5708 -1.24631e-30 0"/>
      <geometry>
        <mesh filename="package://open_duck_mini_description/meshes/foot_bottom_tpu.stl"/>
      </geometry>
    </collision>
    <!-- Part foot_bottom_pla -->
    <visual>
      <origin xyz="0.01656 0.2228 0.10955" rpy="-1.5708 -1.24631e-30 0"/>
      <geometry>
        <mesh filename="package://open_duck_mini_description/meshes/foot_bottom_pla.stl"/>
      </geometry>
      <material name="foot_bottom_pla_material">
        <color rgba="0.305882 0.298039 0.278431 1.0"/>
      </material>
    </visual>
    <collision>
      <origin xyz="0.01656 0.2228 0.10955" rpy="-1.5708 -1.24631e-30 0"/>
      <geometry>
        <mesh filename="package://open_duck_mini_description/meshes/foot_bottom_pla.stl"/>
      </geometry>
    </collision>
    <!-- Part foot_top -->
    <visual>
      <origin xyz="0.01606 0.2223 0.10905" rpy="-1.5708 -1.24631e-30 0"/>
      <geometry>
        <mesh filename="package://open_duck_mini_description/meshes/foot_top.stl"/>
      </geometry>
      <material name="foot_top_material">
        <color rgba="0.980392 0.713725 0.00392157 1.0"/>
      </material>
    </visual>
    <collision>
      <origin xyz="0.01606 0.2223 0.10905" rpy="-1.5708 -1.24631e-30 0"/>
      <geometry>
        <mesh filename="package://open_duck_mini_description/meshes/foot_top.stl"/>
      </geometry>
    </collision>
  </link>
  <!-- Frame left_foot (dummy link + fixed joint) -->
  <link name="left_foot">
    <origin xyz="0 0 0" rpy="0 -0 0"/>
    <inertial>
      <origin xyz="0 0 0" rpy="0 0 0"/>
      <mass value="1e-9"/>
      <inertia ixx="0" ixy="0" ixz="0" iyy="0" iyz="0" izz="0"/>
    </inertial>
  </link>
  <joint name="left_foot_frame" type="fixed">
    <origin xyz="0.0005 -0.036225 0.01955" rpy="-1.5708 -1.24631e-30 -1.77096e-25"/>
    <parent link="foot_assembly"/>
    <child link="left_foot"/>
    <axis xyz="0 0 0"/>
  </joint>
  <!-- Joint from knee_and_ankle_assembly_2 to foot_assembly -->
  <joint name="left_ankle" type="revolute">
    <origin xyz="0 -0.07865 0.0001" rpy="-2.69788e-17 -4.26045e-20 -5.55112e-17"/>
    <parent link="knee_and_ankle_assembly_2"/>
    <child link="foot_assembly"/>
    <axis xyz="0 0 1"/>
    <limit effort="10" velocity="10" lower="-1.5708" upper="1.5708"/>
  </joint>
  <!-- Joint from knee_and_ankle_assembly to knee_and_ankle_assembly_2 -->
  <joint name="left_knee" type="revolute">
    <origin xyz="2.84495e-16 -0.07865 0.0001" rpy="-3.01789e-17 4.26046e-20 -1.98404e-12"/>
    <parent link="knee_and_ankle_assembly"/>
    <child link="knee_and_ankle_assembly_2"/>
    <axis xyz="0 0 1"/>
    <limit effort="10" velocity="10" lower="-1.5708" upper="1.5708"/>
  </joint>
  <!-- Joint from left_roll_to_pitch_assembly to knee_and_ankle_assembly -->
  <joint name="left_hip_pitch" type="revolute">
    <origin xyz="0.07415 3.81693e-16 0.03511" rpy="3.14159 1.5708 0"/>
    <parent link="left_roll_to_pitch_assembly"/>
    <child link="knee_and_ankle_assembly"/>
    <axis xyz="0 0 1"/>
    <limit effort="10" velocity="10" lower="-1.22173" upper="0.523599"/>
  </joint>
  <!-- Joint from hip_roll_assembly to left_roll_to_pitch_assembly -->
  <joint name="left_hip_roll" type="revolute">
    <origin xyz="0.01905 1.30035e-14 -0.046015" rpy="-1.5708 1.10442e-13 1.5708"/>
    <parent link="hip_roll_assembly"/>
    <child link="left_roll_to_pitch_assembly"/>
    <axis xyz="0 0 1"/>
    <limit effort="10" velocity="10" lower="-0.436332" upper="0.436332"/>
  </joint>
  <!-- Joint from trunk_assembly to hip_roll_assembly -->
  <joint name="left_hip_yaw" type="revolute">
    <origin xyz="-0.019 0.035 0.0457409" rpy="2.04385e-15 -1.12182e-14 9.65318e-16"/>
    <parent link="trunk_assembly"/>
    <child link="hip_roll_assembly"/>
    <axis xyz="0 0 1"/>
    <limit effort="10" velocity="10" lower="-0.523599" upper="0.523599"/>
  </joint>
  <!-- Link neck_pitch_assembly -->
  <link name="neck_pitch_assembly">
    <inertial>
      <origin xyz="-5.63137e-06 0.0492968 0.0181786" rpy="0 0 0"/>
      <mass value="0.06618"/>
      <inertia ixx="3.49456e-05" ixy="8.75633e-09" ixz="-2.15592e-09" iyy="1.70231e-05" iyz="-1.85188e-08" izz="2.80043e-05"/>
    </inertial>
    <!-- Part neck_left_sheet -->
    <visual>
      <origin xyz="-0.02 -0.02511 0.01905" rpy="-1.5708 4.87683e-32 0"/>
      <geometry>
        <mesh filename="package://open_duck_mini_description/meshes/neck_left_sheet.stl"/>
      </geometry>
      <material name="neck_left_sheet_material">
        <color rgba="0.223529 0.219608 0.219608 1.0"/>
      </material>
    </visual>
    <collision>
      <origin xyz="-0.02 -0.02511 0.01905" rpy="-1.5708 4.87683e-32 0"/>
      <geometry>
        <mesh filename="package://open_duck_mini_description/meshes/neck_left_sheet.stl"/>
      </geometry>
    </collision>
    <!-- Part neck_right_sheet -->
    <visual>
      <origin xyz="-0.02 -0.02511 0.01905" rpy="-1.5708 3.96984e-18 -5.55112e-17"/>
      <geometry>
        <mesh filename="package://open_duck_mini_description/meshes/neck_right_sheet.stl"/>
      </geometry>
      <material name="neck_right_sheet_material">
        <color rgba="0.223529 0.219608 0.219608 1.0"/>
      </material>
    </visual>
    <collision>
      <origin xyz="-0.02 -0.02511 0.01905" rpy="-1.5708 3.96984e-18 -5.55112e-17"/>
      <geometry>
        <mesh filename="package://open_duck_mini_description/meshes/neck_right_sheet.stl"/>
      </geometry>
    </collision>
    <!-- Part wj_wk00_0123middlecase_56_8 -->
    <visual>
      <origin xyz="-1.95156e-18 0.0405 0.00945" rpy="-1.5708 -1.19636e-16 -1.5708"/>
      <geometry>
        <mesh filename="package://open_duck_mini_description/meshes/wj_wk00_0123middlecase_56.stl"/>
      </geometry>
      <material name="wj_wk00_0123middlecase_56_8_material">
        <color rgba="0.247059 0.243137 0.243137 1.0"/>
      </material>
    </visual>
    <collision>
      <origin xyz="-1.95156e-18 0.0405 0.00945" rpy="-1.5708 -1.19636e-16 -1.5708"/>
      <geometry>
        <mesh filename="package://open_duck_mini_description/meshes/wj_wk00_0123middlecase_56.stl"/>
      </geometry>
    </collision>
    <!-- Part drive_palonier_8 -->
    <visual>
      <origin xyz="-1.95156e-18 0.0405 0.00945" rpy="-1.5708 -1.19636e-16 -1.5708"/>
      <geometry>
        <mesh filename="package://open_duck_mini_description/meshes/drive_palonier.stl"/>
      </geometry>
      <material name="drive_palonier_8_material">
        <color rgba="0.623529 0.666667 0.701961 1.0"/>
      </material>
    </visual>
    <collision>
      <origin xyz="-1.95156e-18 0.0405 0.00945" rpy="-1.5708 -1.19636e-16 -1.5708"/>
      <geometry>
        <mesh filename="package://open_duck_mini_description/meshes/drive_palonier.stl"/>
      </geometry>
    </collision>
    <!-- Part wj_wk00_0124bottomcase_45_8 -->
    <visual>
      <origin xyz="-1.95156e-18 0.0405 0.00945" rpy="-1.5708 -1.19636e-16 -1.5708"/>
      <geometry>
        <mesh filename="package://open_duck_mini_description/meshes/wj_wk00_0124bottomcase_45.stl"/>
      </geometry>
      <material name="wj_wk00_0124bottomcase_45_8_material">
        <color rgba="0.247059 0.243137 0.243137 1.0"/>
      </material>
    </visual>
    <collision>
      <origin xyz="-1.95156e-18 0.0405 0.00945" rpy="-1.5708 -1.19636e-16 -1.5708"/>
      <geometry>
        <mesh filename="package://open_duck_mini_description/meshes/wj_wk00_0124bottomcase_45.stl"/>
      </geometry>
    </collision>
    <!-- Part wj_wk00_0122topcabinetcase_95_8 -->
    <visual>
      <origin xyz="-1.95156e-18 0.0405 0.00945" rpy="-1.5708 -1.19636e-16 -1.5708"/>
      <geometry>
        <mesh filename="package://open_duck_mini_description/meshes/wj_wk00_0122topcabinetcase_95.stl"/>
      </geometry>
      <material name="wj_wk00_0122topcabinetcase_95_8_material">
        <color rgba="0.247059 0.243137 0.243137 1.0"/>
      </material>
    </visual>
    <collision>
      <origin xyz="-1.95156e-18 0.0405 0.00945" rpy="-1.5708 -1.19636e-16 -1.5708"/>
      <geometry>
        <mesh filename="package://open_duck_mini_description/meshes/wj_wk00_0122topcabinetcase_95.stl"/>
      </geometry>
    </collision>
    <!-- Part passive_palonier_8 -->
    <visual>
      <origin xyz="-2.94903e-17 0.0405 0.00655" rpy="-1.5708 -1.19636e-16 -1.5708"/>
      <geometry>
        <mesh filename="package://open_duck_mini_description/meshes/passive_palonier.stl"/>
      </geometry>
      <material name="passive_palonier_8_material">
        <color rgba="0.623529 0.666667 0.701961 1.0"/>
      </material>
    </visual>
    <collision>
      <origin xyz="-2.94903e-17 0.0405 0.00655" rpy="-1.5708 -1.19636e-16 -1.5708"/>
      <geometry>
        <mesh filename="package://open_duck_mini_description/meshes/passive_palonier.stl"/>
      </geometry>
    </collision>
  </link>
  <!-- Link head_pitch_to_yaw -->
  <link name="head_pitch_to_yaw">
    <inertial>
      <origin xyz="-0.00766247 0.026015 0.0186681" rpy="0 0 0"/>
      <mass value="0.0169378"/>
      <inertia ixx="9.43036e-06" ixy="1.35195e-06" ixz="3.05899e-08" iyy="4.64763e-06" iyz="-8.42802e-08" izz="8.02915e-06"/>
    </inertial>
    <!-- Part head_pitch_to_yaw -->
    <visual>
      <origin xyz="-0.02 -0.09111 0.01905" rpy="-1.5708 -3.06106e-32 0"/>
      <geometry>
        <mesh filename="package://open_duck_mini_description/meshes/head_pitch_to_yaw.stl"/>
      </geometry>
      <material name="head_pitch_to_yaw_material">
        <color rgba="0.4 0.4 0.4 1.0"/>
      </material>
    </visual>
    <collision>
      <origin xyz="-0.02 -0.09111 0.01905" rpy="-1.5708 -3.06106e-32 0"/>
      <geometry>
        <mesh filename="package://open_duck_mini_description/meshes/head_pitch_to_yaw.stl"/>
      </geometry>
    </collision>
  </link>
  <!-- Link neck_yaw_assembly -->
  <link name="neck_yaw_assembly">
    <inertial>
      <origin xyz="0.00412907 3.95745e-06 -0.0222828" rpy="0 0 0"/>
      <mass value="0.0918099"/>
      <inertia ixx="3.11706e-05" ixy="4.29429e-09" ixz="-4.41251e-06" iyy="6.94935e-05" iyz="-3.82028e-09" izz="7.04025e-05"/>
    </inertial>
    <!-- Part head_yaw_to_roll -->
    <visual>
      <origin xyz="-0.02 6.12574e-18 -0.14821" rpy="1.30501e-26 -1.26218e-28 2.5243e-28"/>
      <geometry>
        <mesh filename="package://open_duck_mini_description/meshes/head_yaw_to_roll.stl"/>
      </geometry>
      <material name="head_yaw_to_roll_material">
        <color rgba="0.647059 0.647059 0.647059 1.0"/>
      </material>
    </visual>
    <collision>
      <origin xyz="-0.02 6.12574e-18 -0.14821" rpy="1.30501e-26 -1.26218e-28 2.5243e-28"/>
      <geometry>
        <mesh filename="package://open_duck_mini_description/meshes/head_yaw_to_roll.stl"/>
      </geometry>
    </collision>
    <!-- Part wj_wk00_0123middlecase_56_9 -->
    <visual>
      <origin xyz="0.0255 7.18284e-19 -0.00945" rpy="1.5708 -0 -5.95869e-33"/>
      <geometry>
        <mesh filename="package://open_duck_mini_description/meshes/wj_wk00_0123middlecase_56.stl"/>
      </geometry>
      <material name="wj_wk00_0123middlecase_56_9_material">
        <color rgba="0.247059 0.243137 0.243137 1.0"/>
      </material>
    </visual>
    <collision>
      <origin xyz="0.0255 7.18284e-19 -0.00945" rpy="1.5708 -0 -5.95869e-33"/>
      <geometry>
        <mesh filename="package://open_duck_mini_description/meshes/wj_wk00_0123middlecase_56.stl"/>
      </geometry>
    </collision>
    <!-- Part drive_palonier_9 -->
    <visual>
      <origin xyz="0.0255 7.18284e-19 -0.00945" rpy="1.5708 -0 -5.95869e-33"/>
      <geometry>
        <mesh filename="package://open_duck_mini_description/meshes/drive_palonier.stl"/>
      </geometry>
      <material name="drive_palonier_9_material">
        <color rgba="0.623529 0.666667 0.701961 1.0"/>
      </material>
    </visual>
    <collision>
      <origin xyz="0.0255 7.18284e-19 -0.00945" rpy="1.5708 -0 -5.95869e-33"/>
      <geometry>
        <mesh filename="package://open_duck_mini_description/meshes/drive_palonier.stl"/>
      </geometry>
    </collision>
    <!-- Part wj_wk00_0124bottomcase_45_9 -->
    <visual>
      <origin xyz="0.0255 7.18284e-19 -0.00945" rpy="1.5708 -0 -5.95869e-33"/>
      <geometry>
        <mesh filename="package://open_duck_mini_description/meshes/wj_wk00_0124bottomcase_45.stl"/>
      </geometry>
      <material name="wj_wk00_0124bottomcase_45_9_material">
        <color rgba="0.247059 0.243137 0.243137 1.0"/>
      </material>
    </visual>
    <collision>
      <origin xyz="0.0255 7.18284e-19 -0.00945" rpy="1.5708 -0 -5.95869e-33"/>
      <geometry>
        <mesh filename="package://open_duck_mini_description/meshes/wj_wk00_0124bottomcase_45.stl"/>
      </geometry>
    </collision>
    <!-- Part wj_wk00_0122topcabinetcase_95_9 -->
    <visual>
      <origin xyz="0.0255 7.18284e-19 -0.00945" rpy="1.5708 -0 -5.95869e-33"/>
      <geometry>
        <mesh filename="package://open_duck_mini_description/meshes/wj_wk00_0122topcabinetcase_95.stl"/>
      </geometry>
      <material name="wj_wk00_0122topcabinetcase_95_9_material">
        <color rgba="0.247059 0.243137 0.243137 1.0"/>
      </material>
    </visual>
    <collision>
      <origin xyz="0.0255 7.18284e-19 -0.00945" rpy="1.5708 -0 -5.95869e-33"/>
      <geometry>
        <mesh filename="package://open_duck_mini_description/meshes/wj_wk00_0122topcabinetcase_95.stl"/>
      </geometry>
    </collision>
    <!-- Part passive_palonier_9 -->
    <visual>
      <origin xyz="0.0255 3.86654e-16 -0.00655" rpy="1.5708 -0 -5.95869e-33"/>
      <geometry>
        <mesh filename="package://open_duck_mini_description/meshes/passive_palonier.stl"/>
      </geometry>
      <material name="passive_palonier_9_material">
        <color rgba="0.623529 0.666667 0.701961 1.0"/>
      </material>
    </visual>
    <collision>
      <origin xyz="0.0255 3.86654e-16 -0.00655" rpy="1.5708 -0 -5.95869e-33"/>
      <geometry>
        <mesh filename="package://open_duck_mini_description/meshes/passive_palonier.stl"/>
      </geometry>
    </collision>
  </link>
  <!-- Link head_assembly -->
  <link name="head_assembly">
    <inertial>
      <origin xyz="0.0130803 0.000388191 0.0238227" rpy="0 0 0"/>
      <mass value="0.561259"/>
      <inertia ixx="0.00380766" ixy="-1.5656e-05" ixz="0.000117635" iyy="0.00254511" iyz="7.25263e-05" izz="0.00166249"/>
    </inertial>
    <!-- Part right_antenna_holder -->
    <visual>
      <origin xyz="-0.120516 -4.15725e-05 0.0707567" rpy="2.08843 1.55243 2.10702"/>
      <geometry>
        <mesh filename="package://open_duck_mini_description/meshes/right_antenna_holder.stl"/>
      </geometry>
      <material name="right_antenna_holder_material">
        <color rgba="0.980392 0.713725 0.00392157 1.0"/>
      </material>
    </visual>
    <collision>
      <origin xyz="-0.120516 -4.15725e-05 0.0707567" rpy="2.08843 1.55243 2.10702"/>
      <geometry>
        <mesh filename="package://open_duck_mini_description/meshes/right_antenna_holder.stl"/>
      </geometry>
    </collision>
    <!-- Part antenna -->
    <visual>
      <origin xyz="-0.0711521 0.181141 0.0674301" rpy="-1.59373 1.55243 -2.10702"/>
      <geometry>
        <mesh filename="package://open_duck_mini_description/meshes/antenna.stl"/>
      </geometry>
      <material name="antenna_material">
        <color rgba="0.647059 0.647059 0.647059 1.0"/>
      </material>
    </visual>
    <collision>
      <origin xyz="-0.0711521 0.181141 0.0674301" rpy="-1.59373 1.55243 -2.10702"/>
      <geometry>
        <mesh filename="package://open_duck_mini_description/meshes/antenna.stl"/>
      </geometry>
    </collision>
    <!-- Part antenna_2 -->
    <visual>
      <origin xyz="-0.119541 0.000224163 0.0707517" rpy="2.08843 1.55243 2.10702"/>
      <geometry>
        <mesh filename="package://open_duck_mini_description/meshes/antenna.stl"/>
      </geometry>
      <material name="antenna_2_material">
        <color rgba="0.647059 0.647059 0.647059 1.0"/>
      </material>
    </visual>
    <collision>
      <origin xyz="-0.119541 0.000224163 0.0707517" rpy="2.08843 1.55243 2.10702"/>
      <geometry>
        <mesh filename="package://open_duck_mini_description/meshes/antenna.stl"/>
      </geometry>
    </collision>
    <!-- Part left_antenna_holder -->
    <visual>
      <origin xyz="-0.120516 -0.000158428 0.0707567" rpy="-2.08843 1.55243 -2.10702"/>
      <geometry>
        <mesh filename="package://open_duck_mini_description/meshes/left_antenna_holder.stl"/>
      </geometry>
      <material name="left_antenna_holder_material">
        <color rgba="0.980392 0.713725 0.00392157 1.0"/>
      </material>
    </visual>
    <collision>
      <origin xyz="-0.120516 -0.000158428 0.0707567" rpy="-2.08843 1.55243 -2.10702"/>
      <geometry>
        <mesh filename="package://open_duck_mini_description/meshes/left_antenna_holder.stl"/>
      </geometry>
    </collision>
    <!-- Part cam -->
    <visual>
      <origin xyz="0.0242018 -0.0025 -0.0580502" rpy="-3.14159 1.5708 0"/>
      <geometry>
        <mesh filename="package://open_duck_mini_description/meshes/cam.stl"/>
      </geometry>
      <material name="cam_material">
        <color rgba="0.627451 0.627451 0.627451 1.0"/>
      </material>
    </visual>
    <collision>
      <origin xyz="0.0242018 -0.0025 -0.0580502" rpy="-3.14159 1.5708 0"/>
      <geometry>
        <mesh filename="package://open_duck_mini_description/meshes/cam.stl"/>
      </geometry>
    </collision>
    <!-- Part head_bottom_back -->
    <visual>
      <origin xyz="-0.193652 -0.0001 0.0419331" rpy="2.86486e-24 1.5708 0"/>
      <geometry>
        <mesh filename="package://open_duck_mini_description/meshes/head_bottom_back.stl"/>
      </geometry>
      <material name="head_bottom_back_material">
        <color rgba="0.627451 0.627451 0.643137 1.0"/>
      </material>
    </visual>
    <collision>
      <origin xyz="-0.193652 -0.0001 0.0419331" rpy="2.86486e-24 1.5708 0"/>
      <geometry>
        <mesh filename="package://open_duck_mini_description/meshes/head_bottom_back.stl"/>
      </geometry>
    </collision>
    <!-- Part back_head_panel -->
    <visual>
      <origin xyz="-0.193851 -0.0001 0.0419499" rpy="4.5431e-24 1.5708 0"/>
      <geometry>
        <mesh filename="package://open_duck_mini_description/meshes/back_head_panel.stl"/>
      </geometry>
      <material name="back_head_panel_material">
        <color rgba="1 1 1 1.0"/>
      </material>
    </visual>
    <collision>
      <origin xyz="-0.193851 -0.0001 0.0419499" rpy="4.5431e-24 1.5708 0"/>
      <geometry>
        <mesh filename="package://open_duck_mini_description/meshes/back_head_panel.stl"/>
      </geometry>
    </collision>
    <!-- Part eye_panel___left -->
    <visual>
      <origin xyz="-0.193851 -0.0001 0.0419499" rpy="8.82644e-17 1.5708 0"/>
      <geometry>
        <mesh filename="package://open_duck_mini_description/meshes/eye_panel___left.stl"/>
      </geometry>
      <material name="eye_panel___left_material">
        <color rgba="0.494118 0.494118 0.52549 1.0"/>
      </material>
    </visual>
    <collision>
      <origin xyz="-0.193851 -0.0001 0.0419499" rpy="8.82644e-17 1.5708 0"/>
      <geometry>
        <mesh filename="package://open_duck_mini_description/meshes/eye_panel___left.stl"/>
      </geometry>
    </collision>
    <!-- Part lamp -->
    <visual>
      <origin xyz="-0.193851 -0.0001 0.0419499" rpy="1.1602e-16 1.5708 0"/>
      <geometry>
        <mesh filename="package://open_duck_mini_description/meshes/lamp.stl"/>
      </geometry>
      <material name="lamp_material">
        <color rgba="0.627451 0.627451 0.643137 1.0"/>
      </material>
    </visual>
    <collision>
      <origin xyz="-0.193851 -0.0001 0.0419499" rpy="1.1602e-16 1.5708 0"/>
      <geometry>
        <mesh filename="package://open_duck_mini_description/meshes/lamp.stl"/>
      </geometry>
    </collision>
    <!-- Part eye_right_base -->
    <visual>
      <origin xyz="-0.193851 -0.0001 0.0419499" rpy="8.82644e-17 1.5708 0"/>
      <geometry>
        <mesh filename="package://open_duck_mini_description/meshes/eye_right_base.stl"/>
      </geometry>
      <material name="eye_right_base_material">
        <color rgba="0.627451 0.627451 0.643137 1.0"/>
      </material>
    </visual>
    <collision>
      <origin xyz="-0.193851 -0.0001 0.0419499" rpy="8.82644e-17 1.5708 0"/>
      <geometry>
        <mesh filename="package://open_duck_mini_description/meshes/eye_right_base.stl"/>
      </geometry>
    </collision>
    <!-- Part eye_panel___right -->
    <visual>
      <origin xyz="-0.193851 -0.0001 0.0419499" rpy="7.43866e-17 1.5708 0"/>
      <geometry>
        <mesh filename="package://open_duck_mini_description/meshes/eye_panel___right.stl"/>
      </geometry>
      <material name="eye_panel___right_material">
        <color rgba="0.494118 0.494118 0.52549 1.0"/>
      </material>
    </visual>
    <collision>
      <origin xyz="-0.193851 -0.0001 0.0419499" rpy="7.43866e-17 1.5708 0"/>
      <geometry>
        <mesh filename="package://open_duck_mini_description/meshes/eye_panel___right.stl"/>
      </geometry>
    </collision>
    <!-- Part head_roll_mount -->
    <visual>
      <origin xyz="-0.12906 2.54381e-17 0.06095" rpy="-1.8849e-27 1.5708 0"/>
      <geometry>
        <mesh filename="package://open_duck_mini_description/meshes/head_roll_mount.stl"/>
      </geometry>
      <material name="head_roll_mount_material">
        <color rgba="0.501961 0.501961 0.501961 1.0"/>
      </material>
    </visual>
    <collision>
      <origin xyz="-0.12906 2.54381e-17 0.06095" rpy="-1.8849e-27 1.5708 0"/>
      <geometry>
        <mesh filename="package://open_duck_mini_description/meshes/head_roll_mount.stl"/>
      </geometry>
    </collision>
    <!-- Part raspberrypizerow -->
    <visual>
      <origin xyz="0.0319717 0.056 -0.00305" rpy="1.5708 -1.5708 0"/>
      <geometry>
        <mesh filename="package://open_duck_mini_description/meshes/raspberrypizerow.stl"/>
      </geometry>
      <material name="raspberrypizerow_material">
        <color rgba="0.231373 0.380392 0.705882 1.0"/>
      </material>
    </visual>
    <collision>
      <origin xyz="0.0319717 0.056 -0.00305" rpy="1.5708 -1.5708 0"/>
      <geometry>
        <mesh filename="package://open_duck_mini_description/meshes/raspberrypizerow.stl"/>
      </geometry>
    </collision>
    <!-- Part eye_left -->
    <visual>
      <origin xyz="-0.193851 -0.0001 0.0419499" rpy="7.43866e-17 1.5708 0"/>
      <geometry>
        <mesh filename="package://open_duck_mini_description/meshes/eye_left.stl"/>
      </geometry>
      <material name="eye_left_material">
        <color rgba="0.494118 0.494118 0.52549 1.0"/>
      </material>
    </visual>
    <collision>
      <origin xyz="-0.193851 -0.0001 0.0419499" rpy="7.43866e-17 1.5708 0"/>
      <geometry>
        <mesh filename="package://open_duck_mini_description/meshes/eye_left.stl"/>
      </geometry>
    </collision>
    <!-- Part eye_right -->
    <visual>
      <origin xyz="-0.193851 -0.0001 0.0419499" rpy="8.82644e-17 1.5708 0"/>
      <geometry>
        <mesh filename="package://open_duck_mini_description/meshes/eye_right.stl"/>
      </geometry>
      <material name="eye_right_material">
        <color rgba="0.494118 0.494118 0.52549 1.0"/>
      </material>
    </visual>
    <collision>
      <origin xyz="-0.193851 -0.0001 0.0419499" rpy="8.82644e-17 1.5708 0"/>
      <geometry>
        <mesh filename="package://open_duck_mini_description/meshes/eye_right.stl"/>
      </geometry>
    </collision>
    <!-- Part full_speaker -->
    <visual>
      <origin xyz="0.0107458 -0.0615877 0.00942403" rpy="7.11086e-15 1.30458 -1.32344"/>
      <geometry>
        <mesh filename="package://open_duck_mini_description/meshes/full_speaker.stl"/>
      </geometry>
      <material name="full_speaker_material">
        <color rgba="0.647059 0.647059 0.647059 1.0"/>
      </material>
    </visual>
    <collision>
      <origin xyz="0.0107458 -0.0615877 0.00942403" rpy="7.11086e-15 1.30458 -1.32344"/>
      <geometry>
        <mesh filename="package://open_duck_mini_description/meshes/full_speaker.stl"/>
      </geometry>
    </collision>
    <!-- Part roll_bearing_3 -->
    <visual>
      <origin xyz="-6.05295e-08 -0.035 0.167225" rpy="1.11022e-16 -2.6e-07 -8.32668e-17"/>
      <geometry>
        <mesh filename="package://open_duck_mini_description/meshes/roll_bearing.stl"/>
      </geometry>
      <material name="roll_bearing_3_material">
        <color rgba="0.6 0.6 0.6 1.0"/>
      </material>
    </visual>
    <collision>
      <origin xyz="-6.05295e-08 -0.035 0.167225" rpy="1.11022e-16 -2.6e-07 -8.32668e-17"/>
      <geometry>
        <mesh filename="package://open_duck_mini_description/meshes/roll_bearing.stl"/>
      </geometry>
    </collision>
    <!-- Part sg90 -->
    <visual>
      <origin xyz="0.00330552 0.0313341 0.110966" rpy="1.01956e-06 -1.32228 -1.83803"/>
      <geometry>
        <mesh filename="package://open_duck_mini_description/meshes/sg90.stl"/>
      </geometry>
      <material name="sg90_material">
        <color rgba="0.435294 0.670588 0.976471 1.0"/>
      </material>
    </visual>
    <collision>
      <origin xyz="0.00330552 0.0313341 0.110966" rpy="1.01956e-06 -1.32228 -1.83803"/>
      <geometry>
        <mesh filename="package://open_duck_mini_description/meshes/sg90.stl"/>
      </geometry>
    </collision>
    <!-- Part faceplate -->
    <visual>
      <origin xyz="-0.193699 -0.0001 0.04195" rpy="9.08546e-24 1.5708 0"/>
      <geometry>
        <mesh filename="package://open_duck_mini_description/meshes/faceplate.stl"/>
      </geometry>
      <material name="faceplate_material">
        <color rgba="0.74902 0.74902 0.74902 1.0"/>
      </material>
    </visual>
    <collision>
      <origin xyz="-0.193699 -0.0001 0.04195" rpy="9.08546e-24 1.5708 0"/>
      <geometry>
        <mesh filename="package://open_duck_mini_description/meshes/faceplate.stl"/>
      </geometry>
    </collision>
    <!-- Part sg90_2 -->
    <visual>
      <origin xyz="0.00330552 -0.0315341 0.110966" rpy="-1.01956e-06 -1.32228 1.83803"/>
      <geometry>
        <mesh filename="package://open_duck_mini_description/meshes/sg90.stl"/>
      </geometry>
      <material name="sg90_2_material">
        <color rgba="0.435294 0.670588 0.976471 1.0"/>
      </material>
    </visual>
    <collision>
      <origin xyz="0.00330552 -0.0315341 0.110966" rpy="-1.01956e-06 -1.32228 1.83803"/>
      <geometry>
        <mesh filename="package://open_duck_mini_description/meshes/sg90.stl"/>
      </geometry>
    </collision>
    <!-- Part speaker_interface -->
    <visual>
      <origin xyz="-0.123538 -0.00270746 0.0513235" rpy="1.2e-17 1.5708 0"/>
      <geometry>
        <mesh filename="package://open_duck_mini_description/meshes/speaker_interface.stl"/>
      </geometry>
      <material name="speaker_interface_material">
        <color rgba="0.615686 0.811765 0.929412 1.0"/>
      </material>
    </visual>
    <collision>
      <origin xyz="-0.123538 -0.00270746 0.0513235" rpy="1.2e-17 1.5708 0"/>
      <geometry>
        <mesh filename="package://open_duck_mini_description/meshes/speaker_interface.stl"/>
      </geometry>
    </collision>
    <!-- Part speaker_stand -->
    <visual>
      <origin xyz="-0.123538 -0.00270746 0.0513235" rpy="2.73149e-17 1.5708 0"/>
      <geometry>
        <mesh filename="package://open_duck_mini_description/meshes/speaker_stand.stl"/>
      </geometry>
      <material name="speaker_stand_material">
        <color rgba="0.980392 0.713725 0.00392157 1.0"/>
      </material>
    </visual>
    <collision>
      <origin xyz="-0.123538 -0.00270746 0.0513235" rpy="2.73149e-17 1.5708 0"/>
      <geometry>
        <mesh filename="package://open_duck_mini_description/meshes/speaker_stand.stl"/>
      </geometry>
    </collision>
    <!-- Part eye_left_base -->
    <visual>
      <origin xyz="-0.193851 -0.0001 0.0419499" rpy="8.82644e-17 1.5708 0"/>
      <geometry>
        <mesh filename="package://open_duck_mini_description/meshes/eye_left_base.stl"/>
      </geometry>
      <material name="eye_left_base_material">
        <color rgba="0.627451 0.627451 0.643137 1.0"/>
      </material>
    </visual>
    <collision>
      <origin xyz="-0.193851 -0.0001 0.0419499" rpy="8.82644e-17 1.5708 0"/>
      <geometry>
        <mesh filename="package://open_duck_mini_description/meshes/eye_left_base.stl"/>
      </geometry>
    </collision>
    <!-- Part head_bottom_front -->
    <visual>
      <origin xyz="-0.193651 -0.0001 0.0419499" rpy="9.0881e-24 1.5708 0"/>
      <geometry>
        <mesh filename="package://open_duck_mini_description/meshes/head_bottom_front.stl"/>
      </geometry>
      <material name="head_bottom_front_material">
        <color rgba="0.627451 0.627451 0.643137 1.0"/>
      </material>
    </visual>
    <collision>
      <origin xyz="-0.193651 -0.0001 0.0419499" rpy="9.0881e-24 1.5708 0"/>
      <geometry>
        <mesh filename="package://open_duck_mini_description/meshes/head_bottom_front.stl"/>
      </geometry>
    </collision>
    <!-- Part wj_wk00_0123middlecase_56_10 -->
    <visual>
      <origin xyz="0.0255 7.04731e-19 -0.00945" rpy="1.5708 -0 0"/>
      <geometry>
        <mesh filename="package://open_duck_mini_description/meshes/wj_wk00_0123middlecase_56.stl"/>
      </geometry>
      <material name="wj_wk00_0123middlecase_56_10_material">
        <color rgba="0.247059 0.243137 0.243137 1.0"/>
      </material>
    </visual>
    <collision>
      <origin xyz="0.0255 7.04731e-19 -0.00945" rpy="1.5708 -0 0"/>
      <geometry>
        <mesh filename="package://open_duck_mini_description/meshes/wj_wk00_0123middlecase_56.stl"/>
      </geometry>
    </collision>
    <!-- Part drive_palonier_10 -->
    <visual>
      <origin xyz="0.0255 7.04731e-19 -0.00945" rpy="1.5708 -0 0"/>
      <geometry>
        <mesh filename="package://open_duck_mini_description/meshes/drive_palonier.stl"/>
      </geometry>
      <material name="drive_palonier_10_material">
        <color rgba="0.623529 0.666667 0.701961 1.0"/>
      </material>
    </visual>
    <collision>
      <origin xyz="0.0255 7.04731e-19 -0.00945" rpy="1.5708 -0 0"/>
      <geometry>
        <mesh filename="package://open_duck_mini_description/meshes/drive_palonier.stl"/>
      </geometry>
    </collision>
    <!-- Part wj_wk00_0124bottomcase_45_10 -->
    <visual>
      <origin xyz="0.0255 7.04731e-19 -0.00945" rpy="1.5708 -0 0"/>
      <geometry>
        <mesh filename="package://open_duck_mini_description/meshes/wj_wk00_0124bottomcase_45.stl"/>
      </geometry>
      <material name="wj_wk00_0124bottomcase_45_10_material">
        <color rgba="0.247059 0.243137 0.243137 1.0"/>
      </material>
    </visual>
    <collision>
      <origin xyz="0.0255 7.04731e-19 -0.00945" rpy="1.5708 -0 0"/>
      <geometry>
        <mesh filename="package://open_duck_mini_description/meshes/wj_wk00_0124bottomcase_45.stl"/>
      </geometry>
    </collision>
    <!-- Part wj_wk00_0122topcabinetcase_95_10 -->
    <visual>
      <origin xyz="0.0255 7.04731e-19 -0.00945" rpy="1.5708 -0 0"/>
      <geometry>
        <mesh filename="package://open_duck_mini_description/meshes/wj_wk00_0122topcabinetcase_95.stl"/>
      </geometry>
      <material name="wj_wk00_0122topcabinetcase_95_10_material">
        <color rgba="0.247059 0.243137 0.243137 1.0"/>
      </material>
    </visual>
    <collision>
      <origin xyz="0.0255 7.04731e-19 -0.00945" rpy="1.5708 -0 0"/>
      <geometry>
        <mesh filename="package://open_duck_mini_description/meshes/wj_wk00_0122topcabinetcase_95.stl"/>
      </geometry>
    </collision>
    <!-- Part passive_palonier_10 -->
    <visual>
      <origin xyz="0.0255 3.2999e-16 -0.00655" rpy="1.5708 -0 0"/>
      <geometry>
        <mesh filename="package://open_duck_mini_description/meshes/passive_palonier.stl"/>
      </geometry>
      <material name="passive_palonier_10_material">
        <color rgba="0.623529 0.666667 0.701961 1.0"/>
      </material>
    </visual>
    <collision>
      <origin xyz="0.0255 3.2999e-16 -0.00655" rpy="1.5708 -0 0"/>
      <geometry>
        <mesh filename="package://open_duck_mini_description/meshes/passive_palonier.stl"/>
      </geometry>
    </collision>
  </link>
  <!-- Joint from neck_yaw_assembly to head_assembly -->
  <joint name="head_roll" type="revolute">
    <origin xyz="0.04095 3.39979e-16 -0.01915" rpy="1.17527e-16 -1.5708 0"/>
    <parent link="neck_yaw_assembly"/>
    <child link="head_assembly"/>
    <axis xyz="0 0 1"/>
    <limit effort="10" velocity="10" lower="-0.523599" upper="0.523599"/>
  </joint>
  <!-- Joint from head_pitch_to_yaw to neck_yaw_assembly -->
  <joint name="head_yaw" type="revolute">
    <origin xyz="-1.6263e-17 0.057 0.01905" rpy="-1.5708 -2.83246e-15 -2.77679e-28"/>
    <parent link="head_pitch_to_yaw"/>
    <child link="neck_yaw_assembly"/>
    <axis xyz="0 0 1"/>
    <limit effort="10" velocity="10" lower="-2.79253" upper="2.79253"/>
  </joint>
  <!-- Joint from neck_pitch_assembly to head_pitch_to_yaw -->
  <joint name="head_pitch" type="revolute">
    <origin xyz="5.20417e-18 0.066 -6.93889e-18" rpy="-1.19636e-16 3.97006e-18 -9.08773e-15"/>
    <parent link="neck_pitch_assembly"/>
    <child link="head_pitch_to_yaw"/>
    <axis xyz="0 0 1"/>
    <limit effort="10" velocity="10" lower="-0.785398" upper="0.785398"/>
  </joint>
  <!-- Joint from trunk_assembly to neck_pitch_assembly -->
  <joint name="neck_pitch" type="revolute">
    <origin xyz="0.001 0.01915 0.0900009" rpy="1.5708 -3.14089e-14 2.62734e-15"/>
    <parent link="trunk_assembly"/>
    <child link="neck_pitch_assembly"/>
    <axis xyz="0 0 1"/>
    <limit effort="10" velocity="10" lower="-0.349066" upper="1.13446"/>
  </joint>
  <!-- Link hip_roll_assembly_2 -->
  <link name="hip_roll_assembly_2">
    <inertial>
      <origin xyz="0.000795081 -5.46541e-06 -0.03306" rpy="0 0 0"/>
      <mass value="0.06648"/>
      <inertia ixx="2.44411e-05" ixy="2.35658e-09" ixz="-3.81059e-07" iyy="2.81818e-05" iyz="-7.50036e-09" izz="1.42687e-05"/>
    </inertial>
    <!-- Part roll_motor_bottom_2 -->
    <visual>
      <origin xyz="-3.67761e-16 -0.035 0.01905" rpy="4.41706e-18 -5.55035e-17 -3.05311e-16"/>
      <geometry>
        <mesh filename="package://open_duck_mini_description/meshes/roll_motor_bottom.stl"/>
      </geometry>
      <material name="roll_motor_bottom_2_material">
        <color rgba="0.647059 0.647059 0.647059 1.0"/>
      </material>
    </visual>
    <collision>
      <origin xyz="-3.67761e-16 -0.035 0.01905" rpy="4.41706e-18 -5.55035e-17 -3.05311e-16"/>
      <geometry>
        <mesh filename="package://open_duck_mini_description/meshes/roll_motor_bottom.stl"/>
      </geometry>
    </collision>
    <!-- Part roll_motor_top_2 -->
    <visual>
      <origin xyz="0 -0.035 0.01905" rpy="0 -0 -1.3703e-30"/>
      <geometry>
        <mesh filename="package://open_duck_mini_description/meshes/roll_motor_top.stl"/>
      </geometry>
      <material name="roll_motor_top_2_material">
        <color rgba="0.901961 0.901961 0.901961 1.0"/>
      </material>
    </visual>
    <collision>
      <origin xyz="0 -0.035 0.01905" rpy="0 -0 -1.3703e-30"/>
      <geometry>
        <mesh filename="package://open_duck_mini_description/meshes/roll_motor_top.stl"/>
      </geometry>
    </collision>
    <!-- Part wj_wk00_0123middlecase_56_11 -->
    <visual>
      <origin xyz="0.0096 5.94177e-14 -0.020515" rpy="-1.5708 -1.5708 0"/>
      <geometry>
        <mesh filename="package://open_duck_mini_description/meshes/wj_wk00_0123middlecase_56.stl"/>
      </geometry>
      <material name="wj_wk00_0123middlecase_56_11_material">
        <color rgba="0.247059 0.243137 0.243137 1.0"/>
      </material>
    </visual>
    <collision>
      <origin xyz="0.0096 5.94177e-14 -0.020515" rpy="-1.5708 -1.5708 0"/>
      <geometry>
        <mesh filename="package://open_duck_mini_description/meshes/wj_wk00_0123middlecase_56.stl"/>
      </geometry>
    </collision>
    <!-- Part drive_palonier_11 -->
    <visual>
      <origin xyz="0.0096 5.94177e-14 -0.020515" rpy="-1.5708 -1.5708 0"/>
      <geometry>
        <mesh filename="package://open_duck_mini_description/meshes/drive_palonier.stl"/>
      </geometry>
      <material name="drive_palonier_11_material">
        <color rgba="0.623529 0.666667 0.701961 1.0"/>
      </material>
    </visual>
    <collision>
      <origin xyz="0.0096 5.94177e-14 -0.020515" rpy="-1.5708 -1.5708 0"/>
      <geometry>
        <mesh filename="package://open_duck_mini_description/meshes/drive_palonier.stl"/>
      </geometry>
    </collision>
    <!-- Part wj_wk00_0124bottomcase_45_11 -->
    <visual>
      <origin xyz="0.0096 5.94177e-14 -0.020515" rpy="-1.5708 -1.5708 0"/>
      <geometry>
        <mesh filename="package://open_duck_mini_description/meshes/wj_wk00_0124bottomcase_45.stl"/>
      </geometry>
      <material name="wj_wk00_0124bottomcase_45_11_material">
        <color rgba="0.247059 0.243137 0.243137 1.0"/>
      </material>
    </visual>
    <collision>
      <origin xyz="0.0096 5.94177e-14 -0.020515" rpy="-1.5708 -1.5708 0"/>
      <geometry>
        <mesh filename="package://open_duck_mini_description/meshes/wj_wk00_0124bottomcase_45.stl"/>
      </geometry>
    </collision>
    <!-- Part wj_wk00_0122topcabinetcase_95_11 -->
    <visual>
      <origin xyz="0.0096 5.94177e-14 -0.020515" rpy="-1.5708 -1.5708 0"/>
      <geometry>
        <mesh filename="package://open_duck_mini_description/meshes/wj_wk00_0122topcabinetcase_95.stl"/>
      </geometry>
      <material name="wj_wk00_0122topcabinetcase_95_11_material">
        <color rgba="0.247059 0.243137 0.243137 1.0"/>
      </material>
    </visual>
    <collision>
      <origin xyz="0.0096 5.94177e-14 -0.020515" rpy="-1.5708 -1.5708 0"/>
      <geometry>
        <mesh filename="package://open_duck_mini_description/meshes/wj_wk00_0122topcabinetcase_95.stl"/>
      </geometry>
    </collision>
    <!-- Part passive_palonier_11 -->
    <visual>
      <origin xyz="0.0125 5.99382e-14 -0.020515" rpy="-1.5708 -1.5708 0"/>
      <geometry>
        <mesh filename="package://open_duck_mini_description/meshes/passive_palonier.stl"/>
      </geometry>
      <material name="passive_palonier_11_material">
        <color rgba="0.623529 0.666667 0.701961 1.0"/>
      </material>
    </visual>
    <collision>
      <origin xyz="0.0125 5.99382e-14 -0.020515" rpy="-1.5708 -1.5708 0"/>
      <geometry>
        <mesh filename="package://open_duck_mini_description/meshes/passive_palonier.stl"/>
      </geometry>
    </collision>
  </link>
  <!-- Link right_roll_to_pitch_assembly -->
  <link name="right_roll_to_pitch_assembly">
    <inertial>
      <origin xyz="-0.0507497 -0.000417205 0.0204377" rpy="0 0 0"/>
      <mass value="0.07516"/>
      <inertia ixx="2.52676e-05" ixy="-1.31172e-07" ixz="7.32857e-07" iyy="4.15738e-05" iyz="-8.94684e-08" izz="2.82863e-05"/>
    </inertial>
    <!-- Part right_roll_to_pitch -->
    <visual>
      <origin xyz="0.035 -0.065 0.01905" rpy="1.5708 1.5708 0"/>
      <geometry>
        <mesh filename="package://open_duck_mini_description/meshes/right_roll_to_pitch.stl"/>
      </geometry>
      <material name="right_roll_to_pitch_material">
        <color rgba="0.909804 0.572549 0.164706 1.0"/>
      </material>
    </visual>
    <collision>
      <origin xyz="0.035 -0.065 0.01905" rpy="1.5708 1.5708 0"/>
      <geometry>
        <mesh filename="package://open_duck_mini_description/meshes/right_roll_to_pitch.stl"/>
      </geometry>
    </collision>
    <!-- Part wj_wk00_0123middlecase_56_12 -->
    <visual>
      <origin xyz="-0.0647 1.71846e-17 0.00961" rpy="-1.5708 1.5708 0"/>
      <geometry>
        <mesh filename="package://open_duck_mini_description/meshes/wj_wk00_0123middlecase_56.stl"/>
      </geometry>
      <material name="wj_wk00_0123middlecase_56_12_material">
        <color rgba="0.247059 0.243137 0.243137 1.0"/>
      </material>
    </visual>
    <collision>
      <origin xyz="-0.0647 1.71846e-17 0.00961" rpy="-1.5708 1.5708 0"/>
      <geometry>
        <mesh filename="package://open_duck_mini_description/meshes/wj_wk00_0123middlecase_56.stl"/>
      </geometry>
    </collision>
    <!-- Part drive_palonier_12 -->
    <visual>
      <origin xyz="-0.0647 1.71846e-17 0.00961" rpy="-1.5708 1.5708 0"/>
      <geometry>
        <mesh filename="package://open_duck_mini_description/meshes/drive_palonier.stl"/>
      </geometry>
      <material name="drive_palonier_12_material">
        <color rgba="0.623529 0.666667 0.701961 1.0"/>
      </material>
    </visual>
    <collision>
      <origin xyz="-0.0647 1.71846e-17 0.00961" rpy="-1.5708 1.5708 0"/>
      <geometry>
        <mesh filename="package://open_duck_mini_description/meshes/drive_palonier.stl"/>
      </geometry>
    </collision>
    <!-- Part wj_wk00_0124bottomcase_45_12 -->
    <visual>
      <origin xyz="-0.0647 1.71846e-17 0.00961" rpy="-1.5708 1.5708 0"/>
      <geometry>
        <mesh filename="package://open_duck_mini_description/meshes/wj_wk00_0124bottomcase_45.stl"/>
      </geometry>
      <material name="wj_wk00_0124bottomcase_45_12_material">
        <color rgba="0.247059 0.243137 0.243137 1.0"/>
      </material>
    </visual>
    <collision>
      <origin xyz="-0.0647 1.71846e-17 0.00961" rpy="-1.5708 1.5708 0"/>
      <geometry>
        <mesh filename="package://open_duck_mini_description/meshes/wj_wk00_0124bottomcase_45.stl"/>
      </geometry>
    </collision>
    <!-- Part wj_wk00_0122topcabinetcase_95_12 -->
    <visual>
      <origin xyz="-0.0647 1.71846e-17 0.00961" rpy="-1.5708 1.5708 0"/>
      <geometry>
        <mesh filename="package://open_duck_mini_description/meshes/wj_wk00_0122topcabinetcase_95.stl"/>
      </geometry>
      <material name="wj_wk00_0122topcabinetcase_95_12_material">
        <color rgba="0.247059 0.243137 0.243137 1.0"/>
      </material>
    </visual>
    <collision>
      <origin xyz="-0.0647 1.71846e-17 0.00961" rpy="-1.5708 1.5708 0"/>
      <geometry>
        <mesh filename="package://open_duck_mini_description/meshes/wj_wk00_0122topcabinetcase_95.stl"/>
      </geometry>
    </collision>
    <!-- Part passive_palonier_12 -->
    <visual>
      <origin xyz="-0.0676 1.05276e-16 0.00961" rpy="-1.5708 1.5708 0"/>
      <geometry>
        <mesh filename="package://open_duck_mini_description/meshes/passive_palonier.stl"/>
      </geometry>
      <material name="passive_palonier_12_material">
        <color rgba="0.623529 0.666667 0.701961 1.0"/>
      </material>
    </visual>
    <collision>
      <origin xyz="-0.0676 1.05276e-16 0.00961" rpy="-1.5708 1.5708 0"/>
      <geometry>
        <mesh filename="package://open_duck_mini_description/meshes/passive_palonier.stl"/>
      </geometry>
    </collision>
  </link>
  <!-- Link knee_and_ankle_assembly_3 -->
  <link name="knee_and_ankle_assembly_3">
    <inertial>
      <origin xyz="0.00288652 0.0443678 0.0097216" rpy="0 0 0"/>
      <mass value="0.118109"/>
      <inertia ixx="0.00018599" ixy="1.81353e-05" ixz="4.80831e-06" iyy="7.18688e-05" iyz="-1.70964e-05" izz="0.000188981"/>
    </inertial>
    <!-- Part leg_spacer_3 -->
    <visual>
      <origin xyz="0.01606 -0.14365 -0.07215" rpy="1.5708 2.62588e-27 2.77556e-17"/>
      <geometry>
        <mesh filename="package://open_duck_mini_description/meshes/leg_spacer.stl"/>
      </geometry>
      <material name="leg_spacer_3_material">
        <color rgba="0.647059 0.647059 0.647059 1.0"/>
      </material>
    </visual>
    <collision>
      <origin xyz="0.01606 -0.14365 -0.07215" rpy="1.5708 2.62588e-27 2.77556e-17"/>
      <geometry>
        <mesh filename="package://open_duck_mini_description/meshes/leg_spacer.stl"/>
      </geometry>
    </collision>
    <!-- Part left_knee_to_ankle_right_sheet_3 -->
    <visual>
      <origin xyz="0.01606 -0.14365 -0.07205" rpy="1.5708 -2.44384e-30 0"/>
      <geometry>
        <mesh filename="package://open_duck_mini_description/meshes/left_knee_to_ankle_right_sheet.stl"/>
      </geometry>
      <material name="left_knee_to_ankle_right_sheet_3_material">
        <color rgba="0.223529 0.219608 0.219608 1.0"/>
      </material>
    </visual>
    <collision>
      <origin xyz="0.01606 -0.14365 -0.07205" rpy="1.5708 -2.44384e-30 0"/>
      <geometry>
        <mesh filename="package://open_duck_mini_description/meshes/left_knee_to_ankle_right_sheet.stl"/>
      </geometry>
    </collision>
    <!-- Part left_knee_to_ankle_left_sheet_3 -->
    <visual>
      <origin xyz="0.01606 -0.14365 -0.07205" rpy="1.5708 3.42768e-27 -2.77556e-17"/>
      <geometry>
        <mesh filename="package://open_duck_mini_description/meshes/left_knee_to_ankle_left_sheet.stl"/>
      </geometry>
      <material name="left_knee_to_ankle_left_sheet_3_material">
        <color rgba="0.223529 0.219608 0.219608 1.0"/>
      </material>
    </visual>
    <collision>
      <origin xyz="0.01606 -0.14365 -0.07205" rpy="1.5708 3.42768e-27 -2.77556e-17"/>
      <geometry>
        <mesh filename="package://open_duck_mini_description/meshes/left_knee_to_ankle_left_sheet.stl"/>
      </geometry>
    </collision>
    <!-- Part right_lower_cable_guide -->
    <visual>
      <origin xyz="0.03506 -7.40612e-05 0.1092" rpy="1.5708 -2.44384e-30 0"/>
      <geometry>
        <mesh filename="package://open_duck_mini_description/meshes/right_lower_cable_guide.stl"/>
      </geometry>
      <material name="right_lower_cable_guide_material">
        <color rgba="1 1 1 1.0"/>
      </material>
    </visual>
    <collision>
      <origin xyz="0.03506 -7.40612e-05 0.1092" rpy="1.5708 -2.44384e-30 0"/>
      <geometry>
        <mesh filename="package://open_duck_mini_description/meshes/right_lower_cable_guide.stl"/>
      </geometry>
    </collision>
    <!-- Part right_upper_cable_guide -->
    <visual>
      <origin xyz="0.03506 -7.40612e-05 0.109184" rpy="1.5708 -2.44384e-30 0"/>
      <geometry>
        <mesh filename="package://open_duck_mini_description/meshes/right_upper_cable_guide.stl"/>
      </geometry>
      <material name="right_upper_cable_guide_material">
        <color rgba="1 1 1 1.0"/>
      </material>
    </visual>
    <collision>
      <origin xyz="0.03506 -7.40612e-05 0.109184" rpy="1.5708 -2.44384e-30 0"/>
      <geometry>
        <mesh filename="package://open_duck_mini_description/meshes/right_upper_cable_guide.stl"/>
      </geometry>
    </collision>
    <!-- Part right_leg_cover -->
    <visual>
      <origin xyz="0.03506 -7.40612e-05 0.1092" rpy="1.5708 -2.44384e-30 0"/>
      <geometry>
        <mesh filename="package://open_duck_mini_description/meshes/right_leg_cover.stl"/>
      </geometry>
      <material name="right_leg_cover_material">
        <color rgba="1 1 1 1.0"/>
      </material>
    </visual>
    <collision>
      <origin xyz="0.03506 -7.40612e-05 0.1092" rpy="1.5708 -2.44384e-30 0"/>
      <geometry>
        <mesh filename="package://open_duck_mini_description/meshes/right_leg_cover.stl"/>
      </geometry>
    </collision>
    <!-- Part wj_wk00_0123middlecase_56_13 -->
    <visual>
      <origin xyz="-4.16334e-17 0.05315 0.02755" rpy="1.5708 2.77556e-17 -1.5708"/>
      <geometry>
        <mesh filename="package://open_duck_mini_description/meshes/wj_wk00_0123middlecase_56.stl"/>
      </geometry>
      <material name="wj_wk00_0123middlecase_56_13_material">
        <color rgba="0.247059 0.243137 0.243137 1.0"/>
      </material>
    </visual>
    <collision>
      <origin xyz="-4.16334e-17 0.05315 0.02755" rpy="1.5708 2.77556e-17 -1.5708"/>
      <geometry>
        <mesh filename="package://open_duck_mini_description/meshes/wj_wk00_0123middlecase_56.stl"/>
      </geometry>
    </collision>
    <!-- Part drive_palonier_13 -->
    <visual>
      <origin xyz="-4.16334e-17 0.05315 0.02755" rpy="1.5708 2.77556e-17 -1.5708"/>
      <geometry>
        <mesh filename="package://open_duck_mini_description/meshes/drive_palonier.stl"/>
      </geometry>
      <material name="drive_palonier_13_material">
        <color rgba="0.623529 0.666667 0.701961 1.0"/>
      </material>
    </visual>
    <collision>
      <origin xyz="-4.16334e-17 0.05315 0.02755" rpy="1.5708 2.77556e-17 -1.5708"/>
      <geometry>
        <mesh filename="package://open_duck_mini_description/meshes/drive_palonier.stl"/>
      </geometry>
    </collision>
    <!-- Part wj_wk00_0124bottomcase_45_13 -->
    <visual>
      <origin xyz="-4.16334e-17 0.05315 0.02755" rpy="1.5708 2.77556e-17 -1.5708"/>
      <geometry>
        <mesh filename="package://open_duck_mini_description/meshes/wj_wk00_0124bottomcase_45.stl"/>
      </geometry>
      <material name="wj_wk00_0124bottomcase_45_13_material">
        <color rgba="0.247059 0.243137 0.243137 1.0"/>
      </material>
    </visual>
    <collision>
      <origin xyz="-4.16334e-17 0.05315 0.02755" rpy="1.5708 2.77556e-17 -1.5708"/>
      <geometry>
        <mesh filename="package://open_duck_mini_description/meshes/wj_wk00_0124bottomcase_45.stl"/>
      </geometry>
    </collision>
    <!-- Part wj_wk00_0122topcabinetcase_95_13 -->
    <visual>
      <origin xyz="-4.16334e-17 0.05315 0.02755" rpy="1.5708 2.77556e-17 -1.5708"/>
      <geometry>
        <mesh filename="package://open_duck_mini_description/meshes/wj_wk00_0122topcabinetcase_95.stl"/>
      </geometry>
      <material name="wj_wk00_0122topcabinetcase_95_13_material">
        <color rgba="0.247059 0.243137 0.243137 1.0"/>
      </material>
    </visual>
    <collision>
      <origin xyz="-4.16334e-17 0.05315 0.02755" rpy="1.5708 2.77556e-17 -1.5708"/>
      <geometry>
        <mesh filename="package://open_duck_mini_description/meshes/wj_wk00_0122topcabinetcase_95.stl"/>
      </geometry>
    </collision>
    <!-- Part passive_palonier_13 -->
    <visual>
      <origin xyz="-4.64906e-16 0.05315 0.03045" rpy="1.5708 2.77556e-17 -1.5708"/>
      <geometry>
        <mesh filename="package://open_duck_mini_description/meshes/passive_palonier.stl"/>
      </geometry>
      <material name="passive_palonier_13_material">
        <color rgba="0.623529 0.666667 0.701961 1.0"/>
      </material>
    </visual>
    <collision>
      <origin xyz="-4.64906e-16 0.05315 0.03045" rpy="1.5708 2.77556e-17 -1.5708"/>
      <geometry>
        <mesh filename="package://open_duck_mini_description/meshes/passive_palonier.stl"/>
      </geometry>
    </collision>
  </link>
  <!-- Link knee_and_ankle_assembly_4 -->
  <link name="knee_and_ankle_assembly_4">
    <inertial>
      <origin xyz="5.01859e-06 -0.0577465 0.0181136" rpy="0 0 0"/>
      <mass value="0.07259"/>
      <inertia ixx="4.99575e-05" ixy="1.03817e-08" ixz="2.25175e-09" iyy="1.87273e-05" iyz="8.81049e-08" izz="4.23932e-05"/>
    </inertial>
    <!-- Part leg_spacer_4 -->
    <visual>
      <origin xyz="0.01606 0.14365 0.10925" rpy="-1.5708 -1.29214e-27 1.11022e-16"/>
      <geometry>
        <mesh filename="package://open_duck_mini_description/meshes/leg_spacer.stl"/>
      </geometry>
      <material name="leg_spacer_4_material">
        <color rgba="0.647059 0.647059 0.647059 1.0"/>
      </material>
    </visual>
    <collision>
      <origin xyz="0.01606 0.14365 0.10925" rpy="-1.5708 -1.29214e-27 1.11022e-16"/>
      <geometry>
        <mesh filename="package://open_duck_mini_description/meshes/leg_spacer.stl"/>
      </geometry>
    </collision>
    <!-- Part left_knee_to_ankle_right_sheet_4 -->
    <visual>
      <origin xyz="0.01606 0.14365 0.10915" rpy="-1.5708 5.75878e-28 1.11022e-16"/>
      <geometry>
        <mesh filename="package://open_duck_mini_description/meshes/left_knee_to_ankle_right_sheet.stl"/>
      </geometry>
      <material name="left_knee_to_ankle_right_sheet_4_material">
        <color rgba="0.223529 0.219608 0.219608 1.0"/>
      </material>
    </visual>
    <collision>
      <origin xyz="0.01606 0.14365 0.10915" rpy="-1.5708 5.75878e-28 1.11022e-16"/>
      <geometry>
        <mesh filename="package://open_duck_mini_description/meshes/left_knee_to_ankle_right_sheet.stl"/>
      </geometry>
    </collision>
    <!-- Part left_knee_to_ankle_left_sheet_4 -->
    <visual>
      <origin xyz="0.01606 0.14365 0.10915" rpy="-1.5708 -4.09534e-30 4.83177e-30"/>
      <geometry>
        <mesh filename="package://open_duck_mini_description/meshes/left_knee_to_ankle_left_sheet.stl"/>
      </geometry>
      <material name="left_knee_to_ankle_left_sheet_4_material">
        <color rgba="0.223529 0.219608 0.219608 1.0"/>
      </material>
    </visual>
    <collision>
      <origin xyz="0.01606 0.14365 0.10915" rpy="-1.5708 -4.09534e-30 4.83177e-30"/>
      <geometry>
        <mesh filename="package://open_duck_mini_description/meshes/left_knee_to_ankle_left_sheet.stl"/>
      </geometry>
    </collision>
    <!-- Part wj_wk00_0123middlecase_56_14 -->
    <visual>
      <origin xyz="-7.63278e-17 -0.05315 0.00955" rpy="-1.5708 9.79086e-26 1.5708"/>
      <geometry>
        <mesh filename="package://open_duck_mini_description/meshes/wj_wk00_0123middlecase_56.stl"/>
      </geometry>
      <material name="wj_wk00_0123middlecase_56_14_material">
        <color rgba="0.247059 0.243137 0.243137 1.0"/>
      </material>
    </visual>
    <collision>
      <origin xyz="-7.63278e-17 -0.05315 0.00955" rpy="-1.5708 9.79086e-26 1.5708"/>
      <geometry>
        <mesh filename="package://open_duck_mini_description/meshes/wj_wk00_0123middlecase_56.stl"/>
      </geometry>
    </collision>
    <!-- Part drive_palonier_14 -->
    <visual>
      <origin xyz="-7.63278e-17 -0.05315 0.00955" rpy="-1.5708 9.79086e-26 1.5708"/>
      <geometry>
        <mesh filename="package://open_duck_mini_description/meshes/drive_palonier.stl"/>
      </geometry>
      <material name="drive_palonier_14_material">
        <color rgba="0.623529 0.666667 0.701961 1.0"/>
      </material>
    </visual>
    <collision>
      <origin xyz="-7.63278e-17 -0.05315 0.00955" rpy="-1.5708 9.79086e-26 1.5708"/>
      <geometry>
        <mesh filename="package://open_duck_mini_description/meshes/drive_palonier.stl"/>
      </geometry>
    </collision>
    <!-- Part wj_wk00_0124bottomcase_45_14 -->
    <visual>
      <origin xyz="-7.63278e-17 -0.05315 0.00955" rpy="-1.5708 9.79086e-26 1.5708"/>
      <geometry>
        <mesh filename="package://open_duck_mini_description/meshes/wj_wk00_0124bottomcase_45.stl"/>
      </geometry>
      <material name="wj_wk00_0124bottomcase_45_14_material">
        <color rgba="0.247059 0.243137 0.243137 1.0"/>
      </material>
    </visual>
    <collision>
      <origin xyz="-7.63278e-17 -0.05315 0.00955" rpy="-1.5708 9.79086e-26 1.5708"/>
      <geometry>
        <mesh filename="package://open_duck_mini_description/meshes/wj_wk00_0124bottomcase_45.stl"/>
      </geometry>
    </collision>
    <!-- Part wj_wk00_0122topcabinetcase_95_14 -->
    <visual>
      <origin xyz="-7.63278e-17 -0.05315 0.00955" rpy="-1.5708 9.79086e-26 1.5708"/>
      <geometry>
        <mesh filename="package://open_duck_mini_description/meshes/wj_wk00_0122topcabinetcase_95.stl"/>
      </geometry>
      <material name="wj_wk00_0122topcabinetcase_95_14_material">
        <color rgba="0.247059 0.243137 0.243137 1.0"/>
      </material>
    </visual>
    <collision>
      <origin xyz="-7.63278e-17 -0.05315 0.00955" rpy="-1.5708 9.79086e-26 1.5708"/>
      <geometry>
        <mesh filename="package://open_duck_mini_description/meshes/wj_wk00_0122topcabinetcase_95.stl"/>
      </geometry>
    </collision>
    <!-- Part passive_palonier_14 -->
    <visual>
      <origin xyz="1.52656e-16 -0.05315 0.00665" rpy="-1.5708 9.79086e-26 1.5708"/>
      <geometry>
        <mesh filename="package://open_duck_mini_description/meshes/passive_palonier.stl"/>
      </geometry>
      <material name="passive_palonier_14_material">
        <color rgba="0.623529 0.666667 0.701961 1.0"/>
      </material>
    </visual>
    <collision>
      <origin xyz="1.52656e-16 -0.05315 0.00665" rpy="-1.5708 9.79086e-26 1.5708"/>
      <geometry>
        <mesh filename="package://open_duck_mini_description/meshes/passive_palonier.stl"/>
      </geometry>
    </collision>
  </link>
  <!-- Link foot_assembly_2 -->
  <link name="foot_assembly_2">
    <inertial>
      <origin xyz="0.0110718 -0.0246608 0.0190626" rpy="0 0 0"/>
      <mass value="0.07524"/>
      <inertia ixx="1.87482e-05" ixy="1.58839e-06" ixz="-6.52354e-09" iyy="6.74427e-05" iyz="5.67391e-08" izz="6.061e-05"/>
    </inertial>
    <!-- Part foot_side_2 -->
    <visual>
      <origin xyz="0.01606 0.2223 0.10905" rpy="-1.5708 -4.09534e-30 0"/>
      <geometry>
        <mesh filename="package://open_duck_mini_description/meshes/foot_side.stl"/>
      </geometry>
      <material name="foot_side_2_material">
        <color rgba="0.980392 0.713725 0.00392157 1.0"/>
      </material>
    </visual>
    <collision>
      <origin xyz="0.01606 0.2223 0.10905" rpy="-1.5708 -4.09534e-30 0"/>
      <geometry>
        <mesh filename="package://open_duck_mini_description/meshes/foot_side.stl"/>
      </geometry>
    </collision>
    <!-- Part foot_bottom_tpu_2 -->
    <visual>
      <origin xyz="0.01656 0.2228 0.10955" rpy="-1.5708 -4.09534e-30 0"/>
      <geometry>
        <mesh filename="package://open_duck_mini_description/meshes/foot_bottom_tpu.stl"/>
      </geometry>
      <material name="foot_bottom_tpu_2_material">
        <color rgba="0.305882 0.298039 0.278431 1.0"/>
      </material>
    </visual>
    <collision>
      <origin xyz="0.01656 0.2228 0.10955" rpy="-1.5708 -4.09534e-30 0"/>
      <geometry>
        <mesh filename="package://open_duck_mini_description/meshes/foot_bottom_tpu.stl"/>
      </geometry>
    </collision>
    <!-- Part foot_bottom_pla_2 -->
    <visual>
      <origin xyz="0.01656 0.2228 0.10955" rpy="-1.5708 -4.09534e-30 0"/>
      <geometry>
        <mesh filename="package://open_duck_mini_description/meshes/foot_bottom_pla.stl"/>
      </geometry>
      <material name="foot_bottom_pla_2_material">
        <color rgba="0.305882 0.298039 0.278431 1.0"/>
      </material>
    </visual>
    <collision>
      <origin xyz="0.01656 0.2228 0.10955" rpy="-1.5708 -4.09534e-30 0"/>
      <geometry>
        <mesh filename="package://open_duck_mini_description/meshes/foot_bottom_pla.stl"/>
      </geometry>
    </collision>
    <!-- Part foot_top_2 -->
    <visual>
      <origin xyz="0.01606 0.2223 0.10905" rpy="-1.5708 -4.09534e-30 0"/>
      <geometry>
        <mesh filename="package://open_duck_mini_description/meshes/foot_top.stl"/>
      </geometry>
      <material name="foot_top_2_material">
        <color rgba="0.980392 0.713725 0.00392157 1.0"/>
      </material>
    </visual>
    <collision>
      <origin xyz="0.01606 0.2223 0.10905" rpy="-1.5708 -4.09534e-30 0"/>
      <geometry>
        <mesh filename="package://open_duck_mini_description/meshes/foot_top.stl"/>
      </geometry>
    </collision>
  </link>
  <!-- Frame right_foot (dummy link + fixed joint) -->
  <link name="right_foot">
    <origin xyz="0 0 0" rpy="0 -0 0"/>
    <inertial>
      <origin xyz="0 0 0" rpy="0 0 0"/>
      <mass value="1e-9"/>
      <inertia ixx="0" ixy="0" ixz="0" iyy="0" iyz="0" izz="0"/>
    </inertial>
  </link>
  <joint name="right_foot_frame" type="fixed">
    <origin xyz="0.0005 -0.036225 0.01955" rpy="-1.5708 9.68789e-29 0"/>
    <parent link="foot_assembly_2"/>
    <child link="right_foot"/>
    <axis xyz="0 0 0"/>
  </joint>
  <!-- Joint from knee_and_ankle_assembly_4 to foot_assembly_2 -->
  <joint name="right_ankle" type="revolute">
    <origin xyz="-8.32667e-17 -0.07865 0.0001" rpy="1.88569e-26 -1.01508e-25 2.06793e-26"/>
    <parent link="knee_and_ankle_assembly_4"/>
    <child link="foot_assembly_2"/>
    <axis xyz="0 0 1"/>
    <limit effort="10" velocity="10" lower="-1.5708" upper="1.5708"/>
  </joint>
  <!-- Joint from knee_and_ankle_assembly_3 to knee_and_ankle_assembly_4 -->
  <joint name="right_knee" type="revolute">
    <origin xyz="-4.16334e-17 0.07865 0.037" rpy="-3.14159 -2.18222e-26 3.06314e-17"/>
    <parent link="knee_and_ankle_assembly_3"/>
    <child link="knee_and_ankle_assembly_4"/>
    <axis xyz="0 0 1"/>
    <limit effort="10" velocity="10" lower="-1.5708" upper="1.5708"/>
  </joint>
  <!-- Joint from right_roll_to_pitch_assembly to knee_and_ankle_assembly_3 -->
  <joint name="right_hip_pitch" type="revolute">
    <origin xyz="-0.07415 1.76562e-16 0.03511" rpy="-1.40962e-15 1.5708 0"/>
    <parent link="right_roll_to_pitch_assembly"/>
    <child link="knee_and_ankle_assembly_3"/>
    <axis xyz="0 0 1"/>
    <limit effort="10" velocity="10" lower="-0.523599" upper="1.22173"/>
  </joint>
  <!-- Joint from hip_roll_assembly_2 to right_roll_to_pitch_assembly -->
  <joint name="right_hip_roll" type="revolute">
    <origin xyz="0.01905 5.9841e-14 -0.046015" rpy="-1.5708 -1.07345e-13 1.5708"/>
    <parent link="hip_roll_assembly_2"/>
    <child link="right_roll_to_pitch_assembly"/>
    <axis xyz="0 0 1"/>
    <limit effort="10" velocity="10" lower="-0.436332" upper="0.436332"/>
  </joint>
  <!-- Joint from trunk_assembly to hip_roll_assembly_2 -->
  <joint name="right_hip_yaw" type="revolute">
    <origin xyz="-0.019 -0.035 0.0457409" rpy="2.06672e-15 -1.15513e-14 1.93627e-13"/>
    <parent link="trunk_assembly"/>
    <child link="hip_roll_assembly_2"/>
    <axis xyz="0 0 1"/>
    <limit effort="10" velocity="10" lower="-0.523599" upper="0.523599"/>
  </joint>
</robot>
